Workbook

Sheet GDSL
A1: PENJUALAN PRODAK YANG DIPROGAM BERDASARKAN PENCAPAIAN TOKO
A2: TAHUN 2026
A3: PRODUK | B3: G A N D A S I L | J3: TARGET | K3: PELUNASAN | M3: 46072
A4: TOKO | B4: CV. S U B U R M A K M U R - P O N O R O G O | J4: 10000
A5: TANGGAL | B5: No. SPB | C5: K E M A S A N | G5: Jumlah | H5: J U M L A H | J5: KURANG | K5: TANGGAL | L5: TEMPO
C6: B 100 | D6: B 500 | E6: D 100 | F6: D 500 | G6: Kg | H6: RUPIAH | I6: DUS | J6: DUS | L6: HARI
A7: berlaku | B7: 45931 | C7: 1330668 | D7: 1038960 | E7: 1198800 | F7: 932400 | I7: 0.95
A8: 46044 | B8: 24326 | C8: 0 | D8: 300 | E8: 0 | F8: 200 | G8: =C8*14.4+D8*12+E8*14.4+F8*12 -> 6000 | H8: =(C8*C$7+D8*D$7+E8*E$7+F8*F$7)*I$7 -> 473259600 | I8: =C8+D8+E8+F8 -> 500 | J8: =J4-I8 -> 9500 | K8: ='[1]Area 2'!$D$11 -> 46071 | L8: =K8-A8 -> 27
A9: 46081 | B9: 24338 | C9: 150 | D9: 300 | E9: 0 | F9: 100 | G9: =C9*14.4+D9*12+E9*14.4+F9*12 -> 6960 | H9: =(C9*C$7+D9*D$7+E9*E$7+F9*F$7)*I$7 -> 574301790 | I9: =C9+D9+E9+F9 -> 550 | J9: =J8-I9 -> 8950 | K9: ='[1]Area 2'!$D$14 -> 0 | L9: =K9-A9 -> -46081
G10: =C10*14.4+D10*12+E10*14.4+F10*12 -> 0 | H10: =(C10*C$7+D10*D$7+E10*E$7+F10*F$7)*I$7 -> 0 | I10: =C10+D10+E10+F10 -> 0 | J10: =J9-I10 -> 8950 | L10: =K10-A10 -> 0
G11: =C11*14.4+D11*12+E11*14.4+F11*12 -> 0 | H11: =(C11*C$7+D11*D$7+E11*E$7+F11*F$7)*I$7 -> 0 | I11: =C11+D11+E11+F11 -> 0 | J11: =J10-I11 -> 8950 | L11: =K11-A11 -> 0
G12: =C12*14.4+D12*12+E12*14.4+F12*12 -> 0 | H12: =(C12*C$7+D12*D$7+E12*E$7+F12*F$7)*I$7 -> 0 | I12: =C12+D12+E12+F12 -> 0 | J12: =J11-I12 -> 8950 | L12: =K12-A12 -> 0
G13: =C13*14.4+D13*12+E13*14.4+F13*12 -> 0 | H13: =(C13*C$7+D13*D$7+E13*E$7+F13*F$7)*I$7 -> 0 | I13: =C13+D13+E13+F13 -> 0 | J13: =J12-I13 -> 8950 | L13: =K13-A13 -> 0
G14: =C14*14.4+D14*12+E14*14.4+F14*12 -> 0 | H14: =(C14*C$7+D14*D$7+E14*E$7+F14*F$7)*I$7 -> 0 | I14: =C14+D14+E14+F14 -> 0 | J14: =J13-I14 -> 8950 | L14: =K14-A14 -> 0
G15: =C15*14.4+D15*12+E15*14.4+F15*12 -> 0 | H15: =(C15*C$7+D15*D$7+E15*E$7+F15*F$7)*I$7 -> 0 | I15: =C15+D15+E15+F15 -> 0 | J15: =J14-I15 -> 8950 | L15: =K15-A15 -> 0
G16: =C16*14.4+D16*12+E16*14.4+F16*12 -> 0 | H16: =(C16*C$7+D16*D$7+E16*E$7+F16*F$7)*I$7 -> 0 | I16: =C16+D16+E16+F16 -> 0 | J16: =J15-I16 -> 8950 | L16: =K16-A16 -> 0
G17: =C17*14.4+D17*12+E17*14.4+F17*12 -> 0 | H17: =(C17*C$7+D17*D$7+E17*E$7+F17*F$7)*I$7 -> 0 | I17: =C17+D17+E17+F17 -> 0 | J17: =J16-I17 -> 8950 | L17: =K17-A17 -> 0
G18: =C18*14.4+D18*12+E18*14.4+F18*12 -> 0 | H18: =(C18*C$7+D18*D$7+E18*E$7+F18*F$7)*I$7 -> 0 | I18: =C18+D18+E18+F18 -> 0 | J18: =J17-I18 -> 8950 | L18: =K18-A18 -> 0
G19: =C19*14.4+D19*12+E19*14.4+F19*12 -> 0 | H19: =(C19*C$7+D19*D$7+E19*E$7+F19*F$7)*I$7 -> 0 | I19: =C19+D19+E19+F19 -> 0 | J19: =J18-I19 -> 8950 | L19: =K19-A19 -> 0
G20: =C20*14.4+D20*12+E20*14.4+F20*12 -> 0 | H20: =(C20*C$7+D20*D$7+E20*E$7+F20*F$7)*I$7 -> 0 | I20: =C20+D20+E20+F20 -> 0 | J20: =J19-I20 -> 8950 | L20: =K20-A20 -> 0
G21: =C21*14.4+D21*12+E21*14.4+F21*12 -> 0 | H21: =(C21*C$7+D21*D$7+E21*E$7+F21*F$7)*I$7 -> 0 | I21: =C21+D21+E21+F21 -> 0 | J21: =J20-I21 -> 8950 | L21: =K21-A21 -> 0
... G32: =C32*14.4+D32*12+E32*14.4+F32*12 -> 0 | H32: =(C32*C$7+D32*D$7+E32*E$7+F32*F$7)*I$7 -> 0 | I32: =C32+D32+E32+F32 -> 0 | J32: =J31-I32 -> 8950 | L32: =K32-A32 -> 0
A33: Jumlah | C33: =SUM(C8:C32) -> 150 | D33: =SUM(D7:D32) -> 1039560 | E33: =SUM(E8:E32) -> 0 | F33: =SUM(F8:F32) -> 300 | G33: =SUM(G8:G32) -> 12960 | H33: =SUM(H8:H32) -> 1047561390 | I33: =SUM(I7:I32) -> 1050.95 | J33: =J4-I33 -> 8949.05
A34: Total Jumlah Dus | C34: =SUM(D33) -> 1039560 | H34: Capai % | I34: =I33/J4% -> 10.5095 | J34: =J33/J4% -> 89.4905
A36: PRODUK | B36: G A N D A S I L | J36: TARGET | K36: PELUNASAN | M36: 46057
A37: TOKO | B37: PT. M A H A T M A A G R O - N G A N J U K | J37: 5000
A38: TANGGAL | B38: No. SPB | C38: K E M A S A N | G38: Jumlah | H38: J U M L A H | J38: KURANG | K38: TANGGAL | L38: TEMPO
C39: B 100 | D39: B 500 | E39: D 100 | F39: D 500 | G39: Kg | H39: RUPIAH | I39: DUS | J39: DUS | L39: HARI
A40: berlaku | B40: 45931 | C40: 1330668 | D40: 1038960 | E40: 1198800 | F40: 932400 | I40: 0.96
A41: 46036 | B41: 24324 | C41: 50 | D41: 200 | E41: 100 | F41: 150 | G41: =C41*14.4+D41*12+E41*14.4+F41*12 -> 6360 | H41: =(C41*C$40+D41*D$40+E41*E$40+F41*F$40)*I$40 -> 512702784 | I41: =C41+D41+E41+F41 -> 500 | J41: =J37-I41 -> 4500 | L41: =K41-A41 -> -46036
G42: =C42*14.4+D42*12+E42*14.4+F42*12 -> 0 | H42: =(C42*C$40+D42*D$40+E42*E$40+F42*F$40)*I$40 -> 0 | I42: =C42+D42+E42+F42 -> 0 | J42: =J41-I42 -> 4500 | L42: =K42-A42 -> 0
G43: =C43*14.4+D43*12+E43*14.4+F43*12 -> 0 | H43: =(C43*C$40+D43*D$40+E43*E$40+F43*F$40)*I$40 -> 0 | I43: =C43+D43+E43+F43 -> 0 | J43: =J42-I43 -> 4500 | L43: =K43-A43 -> 0
G44: =C44*14.4+D44*12+E44*14.4+F44*12 -> 0 | H44: =(C44*C$40+D44*D$40+E44*E$40+F44*F$40)*I$40 -> 0 | I44: =C44+D44+E44+F44 -> 0 | J44: =J43-I44 -> 4500 | L44: =K44-A44 -> 0
G45: =C45*14.4+D45*12+E45*14.4+F45*12 -> 0 | H45: =(C45*C$40+D45*D$40+E45*E$40+F45*F$40)*I$40 -> 0 | I45: =C45+D45+E45+F45 -> 0 | J45: =J44-I45 -> 4500 | L45: =K45-A45 -> 0
G46: =C46*14.4+D46*12+E46*14.4+F46*12 -> 0 | H46: =(C46*C$40+D46*D$40+E46*E$40+F46*F$40)*I$40 -> 0 | I46: =C46+D46+E46+F46 -> 0 | J46: =J45-I46 -> 4500 | L46: =K46-A46 -> 0
G47: =C47*14.4+D47*12+E47*14.4+F47*12 -> 0 | H47: =(C47*C$40+D47*D$40+E47*E$40+F47*F$40)*I$40 -> 0 | I47: =C47+D47+E47+F47 -> 0 | J47: =J46-I47 -> 4500 | L47: =K47-A47 -> 0
G48: =C48*14.4+D48*12+E48*14.4+F48*12 -> 0 | H48: =(C48*C$40+D48*D$40+E48*E$40+F48*F$40)*I$40 -> 0 | I48: =C48+D48+E48+F48 -> 0 | J48: =J47-I48 -> 4500 | L48: =K48-A48 -> 0
G49: =C49*14.4+D49*12+E49*14.4+F49*12 -> 0 | H49: =(C49*C$40+D49*D$40+E49*E$40+F49*F$40)*I$40 -> 0 | I49: =C49+D49+E49+F49 -> 0 | J49: =J48-I49 -> 4500 | L49: =K49-A49 -> 0
G50: =C50*14.4+D50*12+E50*14.4+F50*12 -> 0 | H50: =(C50*C$40+D50*D$40+E50*E$40+F50*F$40)*I$40 -> 0 | I50: =C50+D50+E50+F50 -> 0 | J50: =J49-I50 -> 4500 | L50: =K50-A50 -> 0
G51: =C51*14.4+D51*12+E51*14.4+F51*12 -> 0 | H51: =(C51*C$40+D51*D$40+E51*E$40+F51*F$40)*I$40 -> 0 | I51: =C51+D51+E51+F51 -> 0 | J51: =J50-I51 -> 4500 | L51: =K51-A51 -> 0
...

Sheet Gdpn
A1: PENJUALAN PRODAK YANG DIPROGAM BERDASARKAN PENCAPAIAN TOKO
A2: =GDSL!A2 -> TAHUN 2026
A3: PRODUK | B3: G A N D A P A N | I3: TARGET | J3: PELUNASAN | L3: 46077
A4: TOKO | B4: S U M B E R M A K M U R AGROINDO - J O M B A N G | I4: 160
A5: TANGGAL | B5: No. SPB | C5: KEMASAN | F5: J U M L A H | I5: KURANG | J5: TANGGAL | K5: TEMPO
C6: MAX | D6: REG | E6: SUB | F6: KG | G6: RUPIAH | H6: DUS | I6: DUS | K6: HARI
A7: berlaku | B7: 45931 | C7: 710400 | D7: 1287600 | E7: 976800
F8: =C8*10+D8*10+E8*10 -> 0 | G8: =(C8*C$7+D8*D$7+E8*E$7) -> 0 | H8: =C8+D8+E8 -> 0 | I8: =I4-H8 -> 160 | K8: =J8-A8 -> 0
F9: =C9*10+D9*10+E9*10 -> 0 | G9: =(C9*C$7+D9*D$7+E9*E$7) -> 0 | H9: =C9+D9+E9 -> 0 | I9: =I8-H9 -> 160 | K9: =J9-A9 -> 0
F10: =C10*10+D10*10+E10*10 -> 0 | G10: =(C10*C$7+D10*D$7+E10*E$7) -> 0 | H10: =C10+D10+E10 -> 0 | I10: =I9-H10 -> 160 | K10: =J10-A10 -> 0
F11: =C11*10+D11*10+E11*10 -> 0 | G11: =(C11*C$7+D11*D$7+E11*E$7) -> 0 | H11: =C11+D11+E11 -> 0 | I11: =I10-H11 -> 160 | K11: =J11-A11 -> 0
F12: =C12*10+D12*10+E12*10 -> 0 | G12: =(C12*C$7+D12*D$7+E12*E$7) -> 0 | H12: =C12+D12+E12 -> 0 | I12: =I11-H12 -> 160 | K12: =J12-A12 -> 0
A13: Jumlah | C13: =SUM(C8:C12) -> 0 | D13: =SUM(D8:D12) -> 0 | E13: =SUM(E8:E12) -> 0 | F13: =SUM(F8:F12) -> 0 | G13: =SUM(G8:G12) -> 0 | H13: =SUM(H8:H12) -> 0 | I13: =I4-H13 -> 160
G14: Capai % | H14: =H13/I4% -> 0 | I14: =I13/I4% -> 100
A16: PRODUK | B16: G A N D A P A N | I16: TARGET | J16: PELUNASAN
A17: TOKO | B17: PT. K A R I S M A I N D O A G R O - J E M B E R | I17: 50
A18: TANGGAL | B18: No. SPB | C18: KEMASAN | F18: J U M L A H | I18: KURANG | J18: TANGGAL | K18: TEMPO
C19: MAX | D19: REG | E19: SUB | F19: KG | G19: RUPIAH | H19: DUS | I19: DUS | K19: HARI
A20: berlaku | B20: 45931 | C20: 710400 | D20: 1287600 | E20: 976800
F21: =C21*10+D21*10+E21*10 -> 0 | G21: =(C21*C$20+D21*D$20+E21*E$20) -> 0 | H21: =C21+D21+E21 -> 0 | I21: =I17-H21 -> 50 | K21: =J21-A21 -> 0
F22: =C22*10+D22*10+E22*10 -> 0 | G22: =(C22*C$20+D22*D$20+E22*E$20) -> 0 | H22: =C22+D22+E22 -> 0 | I22: =I21-H22 -> 50 | K22: =J22-A22 -> 0
F23: =C23*10+D23*10+E23*10 -> 0 | G23: =(C23*C$20+D23*D$20+E23*E$20) -> 0 | H23: =C23+D23+E23 -> 0 | I23: =I22-H23 -> 50 | K23: =J23-A23 -> 0
F24: =C24*10+D24*10+E24*10 -> 0 | G24: =(C24*C$20+D24*D$20+E24*E$20) -> 0 | H24: =C24+D24+E24 -> 0 | I24: =I23-H24 -> 50 | K24: =J24-A24 -> 0
F25: =C25*10+D25*10+E25*10 -> 0 | G25: =(C25*C$20+D25*D$20+E25*E$20) -> 0 | H25: =C25+D25+E25 -> 0 | I25: =I24-H25 -> 50 | K25: =J25-A25 -> 0
A26: Jumlah | C26: =SUM(C21:C25) -> 0 | D26: =SUM(D21:D25) -> 0 | E26: =SUM(E21:E25) -> 0 | F26: =SUM(F21:F25) -> 0 | G26: =SUM(G21:G25) -> 0 | H26: =SUM(H21:H25) -> 0 | I26: =I17-H26 -> 50
G27: Capai % | H27: =H26/I17% -> 0 | I27: =I26/I17% -> 100
A30: PRODUK | B30: G A N D A P A N | I30: TARGET | J30: PELUNASAN | L30: 46062
A31: TOKO | B31: PT. ANUGERAH AGRO MANDIRI - BANYUWANGI | I31: 350
A32: TANGGAL | B32: No. SPB | C32: KEMASAN | F32: J U M L A H | I32: KURANG | J32: TANGGAL | K32: TEMPO
C33: MAX | D33: REG | E33: SUB | F33: KG | G33: RUPIAH | H33: DUS | I33: DUS | K33: HARI
A34: berlaku | B34: 45931 | C34: 710400 | D34: 1287600 | E34: 976800
A35: 46063 | B35: 24285 | C35: 0 | D35: 0 | E35: 30 | F35: =C35*10+D35*10+E35*10 -> 300 | G35: =(C35*C$34+D35*D$34+E35*E$34) -> 29304000 | H35: =C35+D35+E35 -> 30 | I35: =I31-H35 -> 320 | J35: ='[1]Area 4'!$D$43 -> 0 | K35: =J35-A35 -> -46063
A36: 46076 | B36: 24289 | C36: 0 | D36: 19 | E36: 0 | F36: =C36*10+D36*10+E36*10 -> 190 | G36: =(C36*C$34+D36*D$34+E36*E$34) -> 24464400 | H36: =C36+D36+E36 -> 19 | I36: =I35-H36 -> 301 | J36: ='[1]Area 4'!$D$45 -> 0 | K36: =J36-A36 -> -46076
F37: =C37*10+D37*10+E37*10 -> 0 | G37: =(C37*C$34+D37*D$34+E37*E$34) -> 0 | H37: =C37+D37+E37 -> 0 | I37: =I36-H37 -> 301 | K37: =J37-A37 -> 0
F38: =C38*10+D38*10+E38*10 -> 0 | G38: =(C38*C$34+D38*D$34+E38*E$34) -> 0 | H38: =C38+D38+E38 -> 0 | I38: =I37-H38 -> 301 | K38: =J38-A38 -> 0
F39: =C39*10+D39*10+E39*10 -> 0 | G39: =(C39*C$34+D39*D$34+E39*E$34) -> 0 | H39: =C39+D39+E39 -> 0 | I39: =I38-H39 -> 301 | K39: =J39-A39 -> 0
F40: =C40*10+D40*10+E40*10 -> 0 | G40: =(C40*C$34+D40*D$34+E40*E$34) -> 0 | H40: =C40+D40+E40 -> 0 | I40: =I39-H40 -> 301 | K40: =J40-A40 -> 0
F41: =C41*10+D41*10+E41*10 -> 0 | G41: =(C41*C$34+D41*D$34+E41*E$34) -> 0 | H41: =C41+D41+E41 -> 0 | I41: =I40-H41 -> 301 | K41: =J41-A41 -> 0
F42: =C42*10+D42*10+E42*10 -> 0 | G42: =(C42*C$34+D42*D$34+E42*E$34) -> 0 | H42: =C42+D42+E42 -> 0 | I42: =I41-H42 -> 301 | K42: =J42-A42 -> 0
F43: =C43*10+D43*10+E43*10 -> 0 | G43: =(C43*C$34+D43*D$34+E43*E$34) -> 0 | H43: =C43+D43+E43 -> 0 | I43: =I42-H43 -> 301 | K43: =J43-A43 -> 0
...

Sheet Mstfl
A1: PENJUALAN PRODAK YANG DIPROGAM BERDASARKAN PENCAPAIAN TOKO
A2: =GDSL!A2 -> TAHUN 2026
A3: PRODUK | B3: MASTOFOL TRISTAR | I3: TARGET | J3: PELUNASAN | L3: 46077
A4: TOKO | B4: PT. SUMBER MAKMUR AGROINDO - JOMBANG | I4: 300
A5: TANGGAL | B5: NO. SPB | C5: KEMASAN | F5: JUMLAH | I5: KURANG | J5: TANGGAL | K5: TEMPO
C6: 500 CC | D6: 1 LITER | E6: 5 LITER | F6: LITER | G6: RUPIAH | H6: DUS | I6: DUS | K6: HARI
A7: berlaku | B7: 45550 | C7: 1368630 | D7: 1601730 | F7: 0.95
F8: =C8*20+D8*20+E8*20 -> 0 | G8: =(C8*C$7+D8*D$7)*F$7 -> 0 | H8: =C8+D8+E8 -> 0 | I8: =I4-H8 -> 300 | K8: =J8-A8 -> 0
F9: =C9*20+D9*20+E9*20 -> 0 | G9: =(C9*C$7+D9*D$7)*F$7 -> 0 | H9: =C9+D9+E9 -> 0 | I9: =I8-H9 -> 300 | K9: =J9-A9 -> 0
F10: =C10*20+D10*20+E10*20 -> 0 | G10: =(C10*C$7+D10*D$7)*F$7 -> 0 | H10: =C10+D10+E10 -> 0 | I10: =I9-H10 -> 300 | K10: =J10-A10 -> 0
F11: =C11*20+D11*20+E11*20 -> 0 | G11: =(C11*C$7+D11*D$7)*F$7 -> 0 | H11: =C11+D11+E11 -> 0 | I11: =I10-H11 -> 300 | K11: =J11-A11 -> 0
F12: =C12*20+D12*20+E12*20 -> 0 | G12: =(C12*C$7+D12*D$7)*F$7 -> 0 | H12: =C12+D12+E12 -> 0 | I12: =I11-H12 -> 300 | K12: =J12-A12 -> 0
F13: =C13*20+D13*20+E13*20 -> 0 | G13: =(C13*C$7+D13*D$7)*F$7 -> 0 | H13: =C13+D13+E13 -> 0 | I13: =I12-H13 -> 300 | K13: =J13-A13 -> 0
F14: =C14*20+D14*20+E14*20 -> 0 | G14: =(C14*C$7+D14*D$7)*F$7 -> 0 | H14: =C14+D14+E14 -> 0 | I14: =I13-H14 -> 300 | K14: =J14-A14 -> 0
F15: =C15*20+D15*20+E15*20 -> 0 | G15: =(C15*C$7+D15*D$7)*F$7 -> 0 | H15: =C15+D15+E15 -> 0 | I15: =I14-H15 -> 300 | K15: =J15-A15 -> 0
F16: =C16*20+D16*20+E16*20 -> 0 | G16: =(C16*C$7+D16*D$7)*F$7 -> 0 | H16: =C16+D16+E16 -> 0 | I16: =I15-H16 -> 300 | K16: =J16-A16 -> 0
F17: =C17*20+D17*20+E17*20 -> 0 | G17: =(C17*C$7+D17*D$7)*F$7 -> 0 | H17: =C17+D17+E17 -> 0 | I17: =I16-H17 -> 300 | K17: =J17-A17 -> 0
F18: =C18*20+D18*20+E18*20 -> 0 | G18: =(C18*C$7+D18*D$7)*F$7 -> 0 | H18: =C18+D18+E18 -> 0 | I18: =I17-H18 -> 300 | K18: =J18-A18 -> 0
A19: Jumlah | C19: =SUM(C8:C18) -> 0 | D19: =SUM(D8:D18) -> 0 | E19: =SUM(E8:E18) -> 0 | F19: =SUM(F8:F18) -> 0 | G19: =SUM(G8:G18) -> 0 | H19: =SUM(H8:H18) -> 0 | I19: =I4-H19 -> 300 | K19: =J19-B19 -> 0
G20: Capai % | H20: =H19/I4% -> 0 | I20: =I19/I4% -> 100
A23: PRODUK | B23: MASTOFOL TRISTAR | I23: TARGET | J23: PELUNASAN | L23: 46062
A24: TOKO | B24: PT. ANUGERAH AGRO MANDIRI - BANYUWANGI | I24: 500
A25: TANGGAL | B25: NO. SPB | C25: KEMASAN | F25: JUMLAH | I25: KURANG | J25: TANGGAL | K25: TEMPO
C26: 500 CC | D26: 1 LITER | E26: 5 LITER | F26: LITER | G26: RUPIAH | H26: DUS | I26: DUS | K26: HARI
A27: berlaku | B27: 45550 | C27: 1368630 | D27: 1601730 | F27: 0.95
F28: =C28*20+D28*20+E28*20 -> 0 | G28: =(C28*C$27+D28*D$27+E28*E$27)*F$27 -> 0 | H28: =C28+D28+E28 -> 0 | I28: =I24-H28 -> 500 | K28: =J28-A28 -> 0
F29: =C29*20+D29*20+E29*20 -> 0 | G29: =(C29*C$27+D29*D$27+E29*E$27)*F$27 -> 0 | H29: =C29+D29+E29 -> 0 | I29: =I28-H29 -> 500 | K29: =J29-A29 -> 0
F30: =C30*20+D30*20+E30*20 -> 0 | G30: =(C30*C$27+D30*D$27+E30*E$27)*F$27 -> 0 | H30: =C30+D30+E30 -> 0 | I30: =I29-H30 -> 500 | K30: =J30-A30 -> 0
F31: =C31*20+D31*20+E31*20 -> 0 | G31: =(C31*C$27+D31*D$27+E31*E$27)*F$27 -> 0 | H31: =C31+D31+E31 -> 0 | I31: =I30-H31 -> 500 | K31: =J31-A31 -> 0
F32: =C32*20+D32*20+E32*20 -> 0 | G32: =(C32*C$27+D32*D$27+E32*E$27)*F$27 -> 0 | H32: =C32+D32+E32 -> 0 | I32: =I31-H32 -> 500 | K32: =J32-A32 -> 0
F33: =C33*20+D33*20+E33*20 -> 0 | G33: =(C33*C$27+D33*D$27+E33*E$27)*F$27 -> 0 | H33: =C33+D33+E33 -> 0 | I33: =I32-H33 -> 500 | K33: =J33-A33 -> 0
F34: =C34*20+D34*20+E34*20 -> 0 | G34: =(C34*C$27+D34*D$27+E34*E$27)*F$27 -> 0 | H34: =C34+D34+E34 -> 0 | I34: =I33-H34 -> 500 | K34: =J34-A34 -> 0
F35: =C35*20+D35*20+E35*20 -> 0 | G35: =(C35*C$27+D35*D$27+E35*E$27)*F$27 -> 0 | H35: =C35+D35+E35 -> 0 | I35: =I34-H35 -> 500 | K35: =J35-A35 -> 0
A36: Jumlah | C36: =SUM(C28:C35) -> 0 | D36: =SUM(D28:D35) -> 0 | E36: =SUM(E28:E35) -> 0 | F36: =SUM(F28:F35) -> 0 | G36: =SUM(G28:G35) -> 0 | H36: =SUM(H28:H35) -> 0 | I36: =I24-H36 -> 500
G37: Capai % | H37: =H36/I24% -> 0 | I37: =I36/I24% -> 100
A43: Total Jumlah DUS GANDASTAR Toko ditarget | G43: =I24+I4 -> 800
A45: Total Jumlah DUS pencapaian Toko ditarget | G45: =H36+H19 -> 0
A47: Total jumlah kekurangan DUS capai target | G47: =G43-G45 -> 800
A49: Rata-2 % pencapaian target Toko | G49: =G45/G43% -> 0
A51: Rata-2 % kurang pencapaian target Toko | G51: =G47/G43% -> 100
...

Sheet Dkg
A1: PENJUALAN PRODAK YANG DIPROGAM BERDASARKAN PENCAPAIAN TOKO
A2: =GDSL!A2 -> TAHUN 2026
A3: PRODUK | B3: DEKORGAN PLUS | I3: TARGET | J3: PELUNASAN | M3: 45384
A4: TOKO | B4: PT. SUMBER MAKMUR AGROINDO - JOMBANG | I4: 50
A5: TANGGAL | B5: NO. SPB | C5: KEMASAN | F5: JUMLAH | I5: KURANG | J5: TANGGAL | K5: TEMPO
C6: 500 CC | D6: 1 LITER | E6: 5 LITER | F6: LITER | G6: RUPIAH | H6: DUS | I6: DUS | K6: HARI
A7: berlaku | B7: 44866 | C7: 957930 | D7: 906870
F8: =C8*20+D8*20+E8*20 -> 0 | G8: =(C8*C$7+D8*D$7) -> 0 | H8: =C8+D8+E8 -> 0 | I8: =I4-H8 -> 50 | K8: =J8-A8 -> 0
F9: =C9*20+D9*20+E9*20 -> 0 | G9: =(C9*C$7+D9*D$7) -> 0 | H9: =C9+D9+E9 -> 0 | I9: =I8-H9 -> 50 | K9: =J9-A9 -> 0
F10: =C10*20+D10*20+E10*20 -> 0 | G10: =(C10*C$7+D10*D$7) -> 0 | H10: =C10+D10+E10 -> 0 | I10: =I9-H10 -> 50 | K10: =J10-A10 -> 0
F11: =C11*20+D11*20+E11*20 -> 0 | G11: =(C11*C$7+D11*D$7) -> 0 | H11: =C11+D11+E11 -> 0 | I11: =I10-H11 -> 50 | K11: =J11-A11 -> 0
F12: =C12*20+D12*20+E12*20 -> 0 | G12: =(C12*C$7+D12*D$7) -> 0 | H12: =C12+D12+E12 -> 0 | I12: =I11-H12 -> 50 | K12: =J12-A12 -> 0
F13: =C13*20+D13*20+E13*20 -> 0 | G13: =(C13*C$7+D13*D$7) -> 0 | H13: =C13+D13+E13 -> 0 | I13: =I12-H13 -> 50 | K13: =J13-A13 -> 0
F14: =C14*20+D14*20+E14*20 -> 0 | G14: =(C14*C$7+D14*D$7) -> 0 | H14: =C14+D14+E14 -> 0 | I14: =I13-H14 -> 50 | K14: =J14-A14 -> 0
F15: =C15*20+D15*20+E15*20 -> 0 | G15: =(C15*C$7+D15*D$7) -> 0 | H15: =C15+D15+E15 -> 0 | I15: =I14-H15 -> 50 | K15: =J15-A15 -> 0
F16: =C16*20+D16*20+E16*20 -> 0 | G16: =(C16*C$7+D16*D$7) -> 0 | H16: =C16+D16+E16 -> 0 | I16: =I15-H16 -> 50 | K16: =J16-A16 -> 0
F17: =C17*20+D17*20+E17*20 -> 0 | G17: =(C17*C$7+D17*D$7) -> 0 | H17: =C17+D17+E17 -> 0 | I17: =I16-H17 -> 50 | K17: =J17-A17 -> 0
F18: =C18*20+D18*20+E18*20 -> 0 | G18: =(C18*C$7+D18*D$7) -> 0 | H18: =C18+D18+E18 -> 0 | I18: =I17-H18 -> 50 | K18: =J18-A18 -> 0
A19: Jumlah | C19: =SUM(C8:C18) -> 0 | D19: =SUM(D8:D18) -> 0 | E19: =SUM(E8:E18) -> 0 | F19: =SUM(F8:F18) -> 0 | G19: =SUM(G8:G18) -> 0 | H19: =SUM(H8:H18) -> 0 | I19: =I4-H19 -> 50 | K19: =J19-B19 -> 0
G20: Capai % | H20: =H19/I4% -> 0 | I20: =I19/I4% -> 100
A23: PRODUK | B23: DEKORGAN PLUS | I23: TARGET | J23: PELUNASAN | M23: 45377
A24: TOKO | B24: CV. TUNAS ABADI INDOAGRO - BANYUWANGI | I24: 50
A25: TANGGAL | B25: NO. SPB | C25: KEMASAN | F25: JUMLAH | I25: KURANG | J25: TANGGAL | K25: TEMPO
C26: 500 CC | D26: 1 LITER | E26: 5 LITER | F26: LITER | G26: RUPIAH | H26: DUS | I26: DUS | K26: HARI
A27: berlaku | B27: 44866 | C27: 957930 | D27: 906870
F28: =C28*20+D28*20+E28*20 -> 0 | G28: =(C28*C$27+D28*D$27) -> 0 | H28: =C28+D28+E28 -> 0 | I28: =I24-H28 -> 50 | K28: =J28-A28 -> 0
F29: =C29*20+D29*20+E29*20 -> 0 | G29: =(C29*C$27+D29*D$27) -> 0 | H29: =C29+D29+E29 -> 0 | I29: =I28-H29 -> 50 | K29: =J29-A29 -> 0
F30: =C30*20+D30*20+E30*20 -> 0 | G30: =(C30*C$27+D30*D$27) -> 0 | H30: =C30+D30+E30 -> 0 | I30: =I29-H30 -> 50 | K30: =J30-A30 -> 0
F31: =C31*20+D31*20+E31*20 -> 0 | G31: =(C31*C$27+D31*D$27) -> 0 | H31: =C31+D31+E31 -> 0 | I31: =I30-H31 -> 50 | K31: =J31-A31 -> 0
F32: =C32*20+D32*20+E32*20 -> 0 | G32: =(C32*C$27+D32*D$27) -> 0 | H32: =C32+D32+E32 -> 0 | I32: =I31-H32 -> 50 | K32: =J32-A32 -> 0
F33: =C33*20+D33*20+E33*20 -> 0 | G33: =(C33*C$27+D33*D$27) -> 0 | H33: =C33+D33+E33 -> 0 | I33: =I32-H33 -> 50 | K33: =J33-A33 -> 0
F34: =C34*20+D34*20+E34*20 -> 0 | G34: =(C34*C$27+D34*D$27) -> 0 | H34: =C34+D34+E34 -> 0 | I34: =I33-H34 -> 50 | K34: =J34-A34 -> 0
F35: =C35*20+D35*20+E35*20 -> 0 | G35: =(C35*C$27+D35*D$27) -> 0 | H35: =C35+D35+E35 -> 0 | I35: =I34-H35 -> 50 | K35: =J35-A35 -> 0
F36: =C36*20+D36*20+E36*20 -> 0 | G36: =(C36*C$27+D36*D$27) -> 0 | H36: =C36+D36+E36 -> 0 | I36: =I35-H36 -> 50 | K36: =J36-A36 -> 0
F37: =C37*20+D37*20+E37*20 -> 0 | G37: =(C37*C$27+D37*D$27) -> 0 | H37: =C37+D37+E37 -> 0 | I37: =I36-H37 -> 50 | K37: =J37-A37 -> 0
F38: =C38*20+D38*20+E38*20 -> 0 | G38: =(C38*C$27+D38*D$27) -> 0 | H38: =C38+D38+E38 -> 0 | I38: =I37-H38 -> 50 | K38: =J38-A38 -> 0
A39: Jumlah | C39: =SUM(C28:C38) -> 0 | D39: =SUM(D28:D38) -> 0 | E39: =SUM(E28:E38) -> 0 | F39: =SUM(F28:F38) -> 0 | G39: =SUM(G28:G38) -> 0 | H39: =SUM(H28:H38) -> 0 | I39: =I24-H39 -> 50 | K39: =J39-B39 -> 0
G40: Capai % | H40: =H39/I24% -> 0 | I40: =I39/I24% -> 100
A42: Total Jumlah DUS DEKORGANToko ditarget | G42: =I24+I4 -> 100
A44: Total Jumlah DUS pencapaian Toko ditarget | G44: =H39+H19 -> 0
...

Sheet Gdtar
A1: PENJUALAN PRODAK YANG DIPROGAM BERDASARKAN PENCAPAIAN TOKO
A2: =GDSL!A2 -> TAHUN 2026
A3: PRODUK | B3: G A N D A S T A R | I3: TARGET | J3: PELUNASAN | L3: 46062
A4: TOKO | B4: PT. TUNAS ABADI INDOAGRO - BANYUWANGI | I4: 100
A5: TANGGAL | B5: NO. SPB | C5: KEMASAN | F5: JUMLAH | I5: KURANG | J5: TANGGAL | K5: TEMPO
C6: 500 CC | D6: 1 LITER | F6: LITER | G6: RUPIAH | H6: DUS | I6: DUS | K6: HARI
A7: berlaku | B7: 45931 | C7: 399600 | D7: 452880
F8: =C8*20+D8*12 -> 0 | G8: =(C8*C$7+D8*D$7) -> 0 | H8: =C8+D8+E8 -> 0 | I8: =I4-H8 -> 100 | K8: =J8-A8 -> 0
F9: =C9*20+D9*12 -> 0 | G9: =(C9*C$7+D9*D$7) -> 0 | H9: =C9+D9+E9 -> 0 | I9: =I8-H9 -> 100 | K9: =J9-A9 -> 0
F10: =C10*20+D10*12 -> 0 | G10: =(C10*C$7+D10*D$7) -> 0 | H10: =C10+D10+E10 -> 0 | I10: =I9-H10 -> 100 | K10: =J10-A10 -> 0
F11: =C11*20+D11*12 -> 0 | G11: =(C11*C$7+D11*D$7) -> 0 | H11: =C11+D11+E11 -> 0 | I11: =I10-H11 -> 100 | K11: =J11-A11 -> 0
F12: =C12*20+D12*12 -> 0 | G12: =(C12*C$7+D12*D$7) -> 0 | H12: =C12+D12+E12 -> 0 | I12: =I11-H12 -> 100 | K12: =J12-A12 -> 0
F13: =C13*20+D13*12 -> 0 | G13: =(C13*C$7+D13*D$7) -> 0 | H13: =C13+D13+E13 -> 0 | I13: =I12-H13 -> 100 | K13: =J13-A13 -> 0
F14: =C14*20+D14*12 -> 0 | G14: =(C14*C$7+D14*D$7) -> 0 | H14: =C14+D14+E14 -> 0 | I14: =I13-H14 -> 100 | K14: =J14-A14 -> 0
F15: =C15*20+D15*12 -> 0 | G15: =(C15*C$7+D15*D$7) -> 0 | H15: =C15+D15+E15 -> 0 | I15: =I14-H15 -> 100 | K15: =J15-A15 -> 0
F16: =C16*20+D16*12 -> 0 | G16: =(C16*C$7+D16*D$7) -> 0 | H16: =C16+D16+E16 -> 0 | I16: =I15-H16 -> 100 | K16: =J16-A16 -> 0
F17: =C17*20+D17*12 -> 0 | G17: =(C17*C$7+D17*D$7) -> 0 | H17: =C17+D17+E17 -> 0 | I17: =I16-H17 -> 100 | K17: =J17-A17 -> 0
A18: Jumlah | C18: =SUM(C8:C17) -> 0 | D18: =SUM(D8:D17) -> 0 | E18: =SUM(E8:E17) -> 0 | F18: =SUM(F8:F17) -> 0 | G18: =SUM(G8:G17) -> 0 | H18: =SUM(H8:H17) -> 0 | I18: =I4-H18 -> 100
G19: Capai % | H19: =H18/I4% -> 0 | I19: =I18/I4% -> 100
A22: PRODUK | B22: G A N D A S T A R | I22: TARGET | J22: PELUNASAN
A23: TOKO | B23: A G R O P R I M A - D E N P A S A R - B A L I | I23: 300
A24: TANGGAL | B24: NO. SPB | C24: KEMASAN | F24: JUMLAH | I24: KURANG | J24: TANGGAL | K24: TEMPO
C25: 500 CC | D25: 1 LITER | E25: 5 LITER | F25: LITER | G25: RUPIAH | H25: DUS | I25: DUS | K25: HARI
A26: berlaku | B26: 45931 | C26: 399600 | D26: 452880
F27: =C27*20+D27*12 -> 0 | G27: =(C27*C$26+D27*D$26 ) -> 0 | H27: =C27+D27+E27 -> 0 | I27: =I23-H27 -> 300 | K27: =J27-A27 -> 0
F28: =C28*20+D28*12 -> 0 | G28: =(C28*C$26+D28*D$26 ) -> 0 | H28: =C28+D28+E28 -> 0 | I28: =I27-H28 -> 300 | K28: =J28-A28 -> 0
F29: =C29*20+D29*12 -> 0 | G29: =(C29*C$26+D29*D$26 ) -> 0 | H29: =C29+D29+E29 -> 0 | I29: =I28-H29 -> 300 | K29: =J29-A29 -> 0
F30: =C30*20+D30*12 -> 0 | G30: =(C30*C$26+D30*D$26 ) -> 0 | H30: =C30+D30+E30 -> 0 | I30: =I29-H30 -> 300 | K30: =J30-A30 -> 0
F31: =C31*20+D31*12 -> 0 | G31: =(C31*C$26+D31*D$26 ) -> 0 | H31: =C31+D31+E31 -> 0 | I31: =I30-H31 -> 300 | K31: =J31-A31 -> 0
F32: =C32*20+D32*12 -> 0 | G32: =(C32*C$26+D32*D$26 ) -> 0 | H32: =C32+D32+E32 -> 0 | I32: =I31-H32 -> 300 | K32: =J32-A32 -> 0
F33: =C33*20+D33*12 -> 0 | G33: =(C33*C$26+D33*D$26 ) -> 0 | H33: =C33+D33+E33 -> 0 | I33: =I32-H33 -> 300 | K33: =J33-A33 -> 0
F34: =C34*20+D34*12 -> 0 | G34: =(C34*C$26+D34*D$26 ) -> 0 | H34: =C34+D34+E34 -> 0 | I34: =I33-H34 -> 300 | K34: =J34-A34 -> 0
F35: =C35*20+D35*12 -> 0 | G35: =(C35*C$26+D35*D$26 ) -> 0 | H35: =C35+D35+E35 -> 0 | I35: =I34-H35 -> 300 | K35: =J35-A35 -> 0
F36: =C36*20+D36*12 -> 0 | G36: =(C36*C$26+D36*D$26 ) -> 0 | H36: =C36+D36+E36 -> 0 | I36: =I35-H36 -> 300 | K36: =J36-A36 -> 0
F37: =C37*20+D37*12 -> 0 | G37: =(C37*C$26+D37*D$26 ) -> 0 | H37: =C37+D37+E37 -> 0 | I37: =I36-H37 -> 300 | K37: =J37-A37 -> 0
A38: Jumlah | C38: =SUM(C27:C37) -> 0 | D38: =SUM(D27:D37) -> 0 | E38: =SUM(E27:E37) -> 0 | F38: =SUM(F27:F37) -> 0 | G38: =SUM(G27:G37) -> 0 | H38: =SUM(H27:H37) -> 0 | I38: =I23-H38 -> 300
G39: Capai % | H39: =H38/I23% -> 0 | I39: =I38/I23% -> 100
A41: PRODUK | B41: G A N D A S T A R | I41: TARGET | J41: PELUNASAN
A42: TOKO | B42: CV. H I K M A H A G U N G - T U B A N | I42: 100
A43: TANGGAL | B43: NO. SPB | C43: KEMASAN | F43: JUMLAH | I43: KURANG | J43: TANGGAL | K43: TEMPO
...

Sheet Osmocote
A1: PENJUALAN PRODAK YANG DIPROGAM BERDASARKAN PENCAPAIAN TOKO
A2: =GDSL!A2 -> TAHUN 2026
A3: PRODUK | B3: O S M O C O T E | J3: TARGET | K3: PELUNASAN
A4: TOKO | B4: S U M B E R M A K M U R A G R O I N D O - J O M B A N G | J4: 250
A5: TANGGAL | B5: No. SPB | C5: KEMASAN | G5: JUMLAH | H5: JUMLAH | J5: KURANG | K5: TANGGAL | L5: TEMPO
C6: 100 Gr | D6: 500 Gr | E6: 100 Gr | F6: 500 gr+Te | G6: KG | H6: RUPIAH | I6: DUS | J6: DUS | L6: HARI
C7: 6-13-25 | D7: 6-13-25 | E7: Daun&Rata | F7: Daun&Rata
A8: Berlaku | B8: 45550 | C8: 757020 | D8: 1556220 | E8: 767010 | F8: 1633920 | H8: 0.95
G9: =C9*4+D9*12+E9*4+F9*12 -> 0 | H9: =(F9*F$8+C9*C$8+D9*D$8+E9*E$8)*H$8 -> 0 | I9: =C9+D9+E9+F9 -> 0 | J9: =J4-I9 -> 250 | L9: =K9-A9 -> 0
G10: =C10*4+D10*12+E10*4+F10*12 -> 0 | H10: =(F10*F$8+C10*C$8+D10*D$8+E10*E$8)*H$8 -> 0 | I10: =C10+D10+E10+F10 -> 0 | J10: =J9-I10 -> 250 | L10: =K10-A10 -> 0
G11: =C11*4+D11*12+E11*4+F11*12 -> 0 | H11: =(F11*F$8+C11*C$8+D11*D$8+E11*E$8)*H$8 -> 0 | I11: =C11+D11+E11+F11 -> 0 | J11: =J10-I11 -> 250 | L11: =K11-A11 -> 0
G12: =C12*4+D12*12+E12*4+F12*12 -> 0 | H12: =(F12*F$8+C12*C$8+D12*D$8+E12*E$8)*H$8 -> 0 | I12: =C12+D12+E12+F12 -> 0 | J12: =J11-I12 -> 250 | L12: =K12-A12 -> 0
G13: =C13*4+D13*12+E13*4+F13*12 -> 0 | H13: =(F13*F$8+C13*C$8+D13*D$8+E13*E$8)*H$8 -> 0 | I13: =C13+D13+E13+F13 -> 0 | J13: =J12-I13 -> 250 | L13: =K13-A13 -> 0
G14: =C14*4+D14*12+E14*4+F14*12 -> 0 | H14: =(F14*F$8+C14*C$8+D14*D$8+E14*E$8)*H$8 -> 0 | I14: =C14+D14+E14+F14 -> 0 | J14: =J13-I14 -> 250 | L14: =K14-A14 -> 0
G15: =C15*4+D15*12+E15*4+F15*12 -> 0 | H15: =(F15*F$8+C15*C$8+D15*D$8+E15*E$8)*H$8 -> 0 | I15: =C15+D15+E15+F15 -> 0 | J15: =J14-I15 -> 250 | L15: =K15-A15 -> 0
G16: =C16*4+D16*12+E16*4+F16*12 -> 0 | H16: =(F16*F$8+C16*C$8+D16*D$8+E16*E$8)*H$8 -> 0 | I16: =C16+D16+E16+F16 -> 0 | J16: =J15-I16 -> 250 | L16: =K16-A16 -> 0
G17: =C17*4+D17*12+E17*4+F17*12 -> 0 | H17: =(F17*F$8+C17*C$8+D17*D$8+E17*E$8)*H$8 -> 0 | I17: =C17+D17+E17+F17 -> 0 | J17: =J16-I17 -> 250 | L17: =K17-A17 -> 0
G18: =C18*4+D18*12+E18*4+F18*12 -> 0 | H18: =(F18*F$8+C18*C$8+D18*D$8+E18*E$8)*H$8 -> 0 | I18: =C18+D18+E18+F18 -> 0 | J18: =J17-I18 -> 250 | L18: =K18-A18 -> 0
G19: =C19*4+D19*12+E19*4+F19*12 -> 0 | H19: =(F19*F$8+C19*C$8+D19*D$8+E19*E$8)*H$8 -> 0 | I19: =C19+D19+E19+F19 -> 0 | J19: =J18-I19 -> 250 | L19: =K19-A19 -> 0
A20: Jumlah | C20: =SUM(C9:C19) -> 0 | D20: =SUM(D9:D19) -> 0 | E20: =SUM(E9:E19) -> 0 | F20: =SUM(F9:F19) -> 0 | G20: =SUM(G9:G19) -> 0 | H20: =SUM(H9:H19) -> 0 | I20: =SUM(I9:I19) -> 0 | J20: =J4-I20 -> 250
H21: Capai % | I21: =I20/J4% -> 0 | J21: =J20/J4% -> 100
A23: PRODUK | B23: O S M O C O T E | J23: TARGET | K23: PELUNASAN
A24: TOKO | B24: PT. ANUGERAH TANI SEJATI - SURABAYA | J24: 200
A25: TANGGAL | B25: No. SPB | C25: KEMASAN | G25: JUMLAH | H25: JUMLAH | J25: KURANG | K25: TANGGAL | L25: TEMPO
C26: 100 Gr | D26: 500 Gr | E26: 100 Gr | F26: 500 gr+Te | G26: KG | H26: RUPIAH | I26: DUS | J26: DUS | L26: HARI
C27: 6-13-25 | D27: 6-13-25 | E27: Daun&Rata | F27: Daun&Rata
A28: Berlaku | B28: 45931 | C28: 799200 | D28: 1605060 | E28: 821400 | F28: 1704960
A29: 46051 | B29: 24330 | C29: 0 | D29: 1 | E29: 1 | F29: 1 | G29: =C29*4+D29*4+E29*12+F29*12 -> 28 | H29: =(F29*F$28+C29*C$28+D29*D$28+E29*E$28) -> 4131420 | I29: =C29+D29+E29+F29 -> 3 | J29: =J24-I29 -> 197 | K29: ='[1]Area I '!$D$48 -> 46078 | L29: =K29-A29 -> 27
A30: 46071 | B30: 24336 | C30: 1 | D30: 0 | E30: 1 | F30: 0 | G30: =C30*4+D30*4+E30*12+F30*12 -> 16 | H30: =(F30*F$28+C30*C$28+D30*D$28+E30*E$28) -> 1620600 | I30: =C30+D30+E30+F30 -> 2 | J30: =J29-I30 -> 195 | K30: ='[1]Area I '!$D$49 -> 46094 | L30: =K30-A30 -> 23
A31: 46094 | B31: 24340 | C31: 1 | D31: 1 | E31: 1 | F31: 2 | G31: =C31*4+D31*4+E31*12+F31*12 -> 44 | H31: =(F31*F$28+C31*C$28+D31*D$28+E31*E$28) -> 6635580 | I31: =C31+D31+E31+F31 -> 5 | J31: =J30-I31 -> 190 | K31: ='[1]Area I '!$D$50 -> 0 | L31: =K31-A31 -> -46094
G32: =C32*4+D32*4+E32*12+F32*12 -> 0 | H32: =(F32*F$28+C32*C$28+D32*D$28+E32*E$28) -> 0 | I32: =C32+D32+E32+F32 -> 0 | J32: =J31-I32 -> 190 | L32: =K32-A32 -> 0
G33: =C33*4+D33*4+E33*12+F33*12 -> 0 | H33: =(F33*F$28+C33*C$28+D33*D$28+E33*E$28) -> 0 | I33: =C33+D33+E33+F33 -> 0 | J33: =J32-I33 -> 190 | L33: =K33-A33 -> 0
G34: =C34*4+D34*4+E34*12+F34*12 -> 0 | H34: =(F34*F$28+C34*C$28+D34*D$28+E34*E$28) -> 0 | I34: =C34+D34+E34+F34 -> 0 | J34: =J33-I34 -> 190 | L34: =K34-A34 -> 0
G35: =C35*4+D35*4+E35*12+F35*12 -> 0 | H35: =(F35*F$28+C35*C$28+D35*D$28+E35*E$28) -> 0 | I35: =C35+D35+E35+F35 -> 0 | J35: =J34-I35 -> 190 | L35: =K35-A35 -> 0
G36: =C36*4+D36*4+E36*12+F36*12 -> 0 | H36: =(F36*F$28+C36*C$28+D36*D$28+E36*E$28) -> 0 | I36: =C36+D36+E36+F36 -> 0 | J36: =J35-I36 -> 190 | L36: =K36-A36 -> 0
G37: =C37*4+D37*4+E37*12+F37*12 -> 0 | H37: =(F37*F$28+C37*C$28+D37*D$28+E37*E$28) -> 0 | I37: =C37+D37+E37+F37 -> 0 | J37: =J36-I37 -> 190 | L37: =K37-A37 -> 0
G38: =C38*4+D38*4+E38*12+F38*12 -> 0 | H38: =(F38*F$28+C38*C$28+D38*D$28+E38*E$28) -> 0 | I38: =C38+D38+E38+F38 -> 0 | J38: =J37-I38 -> 190 | L38: =K38-A38 -> 0
G39: =C39*4+D39*4+E39*12+F39*12 -> 0 | H39: =(F39*F$28+C39*C$28+D39*D$28+E39*E$28) -> 0 | I39: =C39+D39+E39+F39 -> 0 | J39: =J38-I39 -> 190 | L39: =K39-A39 -> 0
G40: =C40*4+D40*4+E40*12+F40*12 -> 0 | H40: =(F40*F$28+C40*C$28+D40*D$28+E40*E$28) -> 0 | I40: =C40+D40+E40+F40 -> 0 | J40: =J39-I40 -> 190 | L40: =K40-A40 -> 0
G41: =C41*4+D41*4+E41*12+F41*12 -> 0 | H41: =(F41*F$28+C41*C$28+D41*D$28+E41*E$28) -> 0 | I41: =C41+D41+E41+F41 -> 0 | J41: =J40-I41 -> 190 | L41: =K41-A41 -> 0
...

Sheet Dkm Cair
A1: PENJUALAN PRODAK YANG DIPROGAM BERDASARKAN PENCAPAIAN TOKO
A2: =GDSL!A2 -> TAHUN 2026
A3: PRODUK | B3: D E K A M O N 22 , 43 L | I3: TARGET | J3: PELUNASAN | L3: 46077
A4: TOKO | B4: PT. S U M B E R M A K M U R - J O M B A N G | I4: 400
A5: TANGGAL | B5: No. SPB | C5: KEMASAN | F5: J U M L A H | I5: KURANG | J5: TANGGAL | K5: TEMPO
C6: 100 CC | D6: 500 CC | E6: 1 Liter | F6: LITER | G6: RUPIAH | H6: DUS | I6: DUS | K6: HARI
A7: berlaku | B7: 45931 | C7: 985680 | D7: 1287600 | F7: 0.97
F8: =(C8*5+D8*20+E8*12) -> 0 | G8: =(C8*C$7+D8*D$7+E8*E$7)*F$7 -> 0 | H8: =C8+D8+E8 -> 0 | I8: =I4-H8 -> 400 | K8: =J8-A8 -> 0
F9: =(C9*5+D9*20+E9*12) -> 0 | G9: =(C9*C$7+D9*D$7+E9*E$7)*F$7 -> 0 | H9: =C9+D9+E9 -> 0 | I9: =I8-H9 -> 400 | K9: =J9-A9 -> 0
F10: =(C10*5+D10*20+E10*12) -> 0 | G10: =(C10*C$7+D10*D$7+E10*E$7)*F$7 -> 0 | H10: =C10+D10+E10 -> 0 | I10: =I9-H10 -> 400 | K10: =J10-A10 -> 0
A11: Jumlah | C11: =SUM(C8:C10) -> 0 | D11: =SUM(D8:D10) -> 0 | E11: =SUM(E8:E10) -> 0 | F11: =SUM(F8:F10) -> 0 | G11: =SUM(G8:G10) -> 0 | H11: =SUM(H8:H10) -> 0 | I11: =I4-H11 -> 400
G12: Capai % | H12: =H11/I4% -> 0 | I12: =I11/I4% -> 100
A14: PRODUK | B14: D E K A M O N 22 , 43 L | I14: TARGET | J14: PELUNASAN | L14: 46072
A15: TOKO | B15: CV. S U B U R M A K M U R - P O N O R O G O | I15: 600
A16: TANGGAL | B16: No. SPB | C16: KEMASAN | F16: J U M L A H | I16: KURANG | J16: TANGGAL | K16: TEMPO
C17: 100 CC | D17: 500 CC | E17: 1 Liter | F17: LITER | G17: RUPIAH | H17: DUS | I17: DUS | K17: HARI
A18: berlaku | B18: 45931 | C18: 985680 | D18: 1287600 | F18: 0.97
A19: 46044 | B19: 24327 | C19: 50 | D19: 0 | E19: 0 | F19: =(C19*5+D19*20+E19*12) -> 250 | G19: =(C19*C$18+D19*D$18+E19*E$18)*F$18 -> 47805480 | H19: =C19+D19+E19 -> 50 | I19: =I15-H19 -> 550 | J19: ='[1]Area 2'!$D$12 -> 0 | K19: =J19-A19 -> -46044
F20: =(C20*5+D20*20+E20*12) -> 0 | G20: =(C20*C$18+D20*D$18+E20*E$18)*F$18 -> 0 | H20: =C20+D20+E20 -> 0 | I20: =I19-H20 -> 550 | K20: =J20-A20 -> 0
F21: =(C21*5+D21*20+E21*12) -> 0 | G21: =(C21*C$18+D21*D$18+E21*E$18)*F$18 -> 0 | H21: =C21+D21+E21 -> 0 | I21: =I20-H21 -> 550 | K21: =J21-A21 -> 0
F22: =(C22*5+D22*20+E22*12) -> 0 | G22: =(C22*C$18+D22*D$18+E22*E$18)*F$18 -> 0 | H22: =C22+D22+E22 -> 0 | I22: =I21-H22 -> 550 | K22: =J22-A22 -> 0
F23: =(C23*5+D23*20+E23*12) -> 0 | G23: =(C23*C$18+D23*D$18+E23*E$18)*F$18 -> 0 | H23: =C23+D23+E23 -> 0 | I23: =I22-H23 -> 550 | K23: =J23-A23 -> 0
F24: =(C24*5+D24*20+E24*12) -> 0 | G24: =(C24*C$18+D24*D$18+E24*E$18)*F$18 -> 0 | H24: =C24+D24+E24 -> 0 | I24: =I23-H24 -> 550 | K24: =J24-A24 -> 0
F25: =(C25*5+D25*20+E25*12) -> 0 | G25: =(C25*C$18+D25*D$18+E25*E$18)*F$18 -> 0 | H25: =C25+D25+E25 -> 0 | I25: =I24-H25 -> 550 | K25: =J25-A25 -> 0
F26: =(C26*5+D26*20+E26*12) -> 0 | G26: =(C26*C$18+D26*D$18+E26*E$18)*F$18 -> 0 | H26: =C26+D26+E26 -> 0 | I26: =I25-H26 -> 550 | K26: =J26-A26 -> 0
F27: =(C27*5+D27*20+E27*12) -> 0 | G27: =(C27*C$18+D27*D$18+E27*E$18)*F$18 -> 0 | H27: =C27+D27+E27 -> 0 | I27: =I26-H27 -> 550 | K27: =J27-A27 -> 0
F28: =(C28*5+D28*20+E28*12) -> 0 | G28: =(C28*C$18+D28*D$18+E28*E$18)*F$18 -> 0 | H28: =C28+D28+E28 -> 0 | I28: =I27-H28 -> 550 | K28: =J28-A28 -> 0
F29: =(C29*5+D29*20+E29*12) -> 0 | G29: =(C29*C$18+D29*D$18+E29*E$18)*F$18 -> 0 | H29: =C29+D29+E29 -> 0 | I29: =I28-H29 -> 550 | K29: =J29-A29 -> 0
A30: Jumlah | C30: =SUM(C19:C29) -> 50 | D30: =SUM(D19:D29) -> 0 | E30: =SUM(E19:E29) -> 0 | F30: =SUM(F19:F29) -> 250 | G30: =SUM(G19:G29) -> 47805480 | H30: =SUM(H19:H29) -> 50 | I30: =I15-H30 -> 550
G31: Capai % | H31: =H30/I15% -> 8.3333333 | I31: =I30/I15% -> 91.666667
A34: PRODUK | B34: D E K A M O N 22 , 43 L | I34: TARGET | J34: PELUNASAN | L34: 46062
A35: TOKO | B35: K A R I S M A I N D O A G R O - J E M B E R | I35: 1200
A36: TANGGAL | B36: No. SPB | C36: KEMASAN | F36: J U M L A H | I36: KURANG | J36: TANGGAL | K36: TEMPO
C37: 100 CC | D37: 500 CC | E37: 1 Liter | F37: LITER | G37: RUPIAH | H37: DUS | I37: DUS | K37: HARI
A38: berlaku | B38: 45931 | C38: 985680 | D38: 1287600 | E38: 1518480 | F38: 0.97
A39: 46034 | B39: 24278 | C39: 0 | D39: 0 | E39: 10 | F39: =(C39*5+D39*20+E39*12) -> 120 | G39: =(C39*C$38+D39*D$38+E39*E$38)*F$38 -> 14729256 | H39: =C39+D39+E39 -> 10 | I39: =I35-H39 -> 1190 | J39: ='[1]Area 3'!$D$12 -> 46063 | K39: =J39-A39 -> 29
A40: 46055 | B40: 24282 | C40: 0 | D40: 100 | E40: 25 | F40: =(C40*5+D40*20+E40*12) -> 2300 | G40: =(C40*C$38+D40*D$38+E40*E$38)*F$38 -> 161720340 | H40: =C40+D40+E40 -> 125 | I40: =I39-H40 -> 1065 | J40: ='[1]Area 3'!$D$15 -> 46084 | K40: =J40-A40 -> 29
F41: =(C41*5+D41*20+E41*12) -> 0 | G41: =(C41*C$38+D41*D$38+E41*E$38)*F$38 -> 0 | H41: =C41+D41+E41 -> 0 | I41: =I40-H41 -> 1065 | K41: =J41-A41 -> 0
F42: =(C42*5+D42*20+E42*12) -> 0 | G42: =(C42*C$38+D42*D$38+E42*E$38)*F$38 -> 0 | H42: =C42+D42+E42 -> 0 | I42: =I41-H42 -> 1065 | K42: =J42-A42 -> 0
F43: =(C43*5+D43*20+E43*12) -> 0 | G43: =(C43*C$38+D43*D$38+E43*E$38)*F$38 -> 0 | H43: =C43+D43+E43 -> 0 | I43: =I42-H43 -> 1065 | K43: =J43-A43 -> 0
...

Sheet Dkm 1,2
A1: PENJUALAN PRODAK YANG DIPROGAM BERDASARKAN PENCAPAIAN TOKO
A2: =GDSL!A2 -> TAHUN 2026
A3: PRODUK | B3: D E K A M O N 1 , 2 G | G3: TARGET | H3: PELUNASAN | J3: 46077
A4: TOKO | B4: SUMBER MAKMUR AGROINDO - JOMBANG | G4: 100
A5: TANGGAL | B5: NO. SPB | C5: KEMASAN | D5: JUMLAH | E5: J U M L A H | G5: KURANG | H5: TANGGAL | I5: TEMPO
C6: 1 KG | D6: KG | E6: RUPIAH | F6: DUS | G6: DUS | I6: HARI
A7: berlaku | B7: 45931 | C7: 777000 | D7: 10
A8: 46048 | B8: 24328 | C8: 35 | D8: =(C8*10 ) -> 350 | E8: =(C8*C$7) -> 27195000 | F8: =C8 -> 35 | G8: =G4-F8 -> 65 | H8: ='[1]Area I '!$D$13 -> 46083 | I8: =H8-A8 -> 35
D9: =(C9*10 ) -> 0 | E9: =(C9*C$7) -> 0 | F9: =C9 -> 0 | G9: =G8-F9 -> 65 | I9: =H9-A9 -> 0
D10: =(C10*10 ) -> 0 | E10: =(C10*C$7) -> 0 | F10: =C10 -> 0 | G10: =G9-F10 -> 65 | I10: =H10-A10 -> 0
D11: =(C11*10 ) -> 0 | E11: =(C11*C$7) -> 0 | F11: =C11 -> 0 | G11: =G10-F11 -> 65 | I11: =H11-A11 -> 0
D12: =(C12*10 ) -> 0 | E12: =(C12*C$7) -> 0 | F12: =C12 -> 0 | G12: =G11-F12 -> 65 | I12: =H12-A12 -> 0
D13: =(C13*10 ) -> 0 | E13: =(C13*C$7) -> 0 | F13: =C13 -> 0 | G13: =G12-F13 -> 65 | I13: =H13-A13 -> 0
A14: Jumlah | C14: =SUM(C8:C13) -> 35 | D14: =SUM(D8:D13) -> 350 | E14: =SUM(E8:E13) -> 27195000 | F14: =SUM(F8:F13) -> 35 | G14: =G4-F14 -> 65
E15: Capai % | F15: =F14/G4% -> 35 | G15: =G14/G4% -> 65
A18: PRODUK | B18: D E K A M O N 1 , 2 G | G18: TARGET | H18: PELUNASAN | J18: 46062
A19: TOKO | B19: PT. TUNAS ABADI INDOAGRO - BANYUWANGI | G19: 100
A20: TANGGAL | B20: NO. SPB | C20: KEMASAN | D20: JUMLAH | E20: J U M L A H | G20: KURANG | H20: TANGGAL | I20: TEMPO
C21: 1 KG | D21: KG | E21: RUPIAH | F21: DUS | G21: DUS | I21: HARI
A22: berlaku | B22: 45550 | C22: 735930 | D22: 10
E23: =(C23*C$22) -> 0 | F23: =C23 -> 0 | G23: =G19-F23 -> 100 | I23: =H23-A23 -> 0
E24: =(C24*C$22) -> 0 | F24: =C24 -> 0 | G24: =G23-G24 -> 0 | I24: =H24-A24 -> 0
D25: =(C25*10 ) -> 0 | E25: =(C25*C$22) -> 0 | F25: =C25 -> 0 | G25: =G24-G25 -> 0 | I25: =H25-A25 -> 0
D26: =(C26*10 ) -> 0 | E26: =(C26*C$22) -> 0 | F26: =C26 -> 0 | G26: =G25-G26 -> 0 | I26: =H26-A26 -> 0
A27: Jumlah | C27: =SUM(C23:C23) -> 0 | D27: =SUM(D23:D26) -> 0 | E27: =SUM(E23:E23) -> 0 | F27: =SUM(F23:F23) -> 0 | G27: =G19-F27 -> 100
E28: Capai % | F28: =F27/G19% -> 0 | G28: =G27/G19% -> 100
A31: PRODUK | B31: D E K A M O N 1 , 2 G | G31: TARGET | H31: PELUNASAN
A32: TOKO | B32: PT. SENTRA AGRONUSA BHAKTI - SURABAYA | G32: 100
A33: TANGGAL | C33: KEMASAN | D33: JUMLAH | E33: J U M L A H | G33: KURANG | H33: TANGGAL | I33: TEMPO
C34: 1 KG | D34: KG | E34: RUPIAH | F34: DUS | G34: DUS | I34: HARI
A35: berlaku | B35: 45550 | C35: 735930 | D35: 10
D36: =(C36*10 ) -> 0 | E36: =(C36*C$35) -> 0 | F36: =C36 -> 0 | G36: =G32-F36 -> 100 | I36: =H36-A36 -> 0
D37: =(C37*10 ) -> 0 | E37: =(C37*C$35) -> 0 | F37: =C37 -> 0 | G37: =G36-G37 -> 0 | I37: =H37-A37 -> 0
D38: =(C38*10 ) -> 0 | E38: =(C38*C$35) -> 0 | F38: =C38 -> 0 | G38: =G37-G38 -> 0 | I38: =H38-A38 -> 0
D39: =(C39*10 ) -> 0 | E39: =(C39*C$35) -> 0 | F39: =C39 -> 0 | G39: =G38-G39 -> 0 | I39: =H39-A39 -> 0
D40: =(C40*10 ) -> 0 | E40: =(C40*C$35) -> 0 | F40: =C40 -> 0 | G40: =G39-G40 -> 0 | I40: =H40-A40 -> 0
D41: =(C41*10 ) -> 0 | E41: =(C41*C$35) -> 0
D42: =(C42*10 ) -> 0 | E42: =(C42*C$35) -> 0
A43: Jumlah | C43: =SUM(C36:C42) -> 0 | D43: =SUM(D36:D42) -> 0 | E43: =SUM(E36:E42) -> 0 | F43: =SUM(F36:F42) -> 0 | G43: =G32-F43 -> 100
E44: Capai % | F44: =F43/G32% -> 0 | G44: =G43/G32% -> 100
...

Sheet Dekabond
A1: PENJUALAN PRODAK YANG DIPROGAM BERDASARKAN PENCAPAIAN TOKO
A2: =GDSL!A2 -> TAHUN 2026
A3: PRODUK | B3: D E K A B O N D | H3: TARGET | I3: PELUNASAN | K3: 46072
A4: TOKO | B4: CV. SUBUR MAKMUR - PONOROGO | H4: 150
A5: TANGGAL | B5: NO. SPB | C5: KEMASAN | F5: J U M L A H | H5: KURANG | I5: TANGGAL | J5: TEMPO
C6: 100 cc | D6: 500 cc | E6: 1000 cc | F6: DUS | G6: RUPIAH | H6: KG | J6: HARI
A7: berlaku | C7: 1276500 | D7: 2220000
A8: 46072 | B8: 24335 | C8: 0 | D8: 25 | E8: 0 | F8: =C8+D8+E8 -> 25 | G8: =(C8*C$7+D8*D$7+E8*E$7) -> 55500000 | H8: =H4-F8 -> 125 | I8: ='[1]Area 2'!$D$13 -> 0 | J8: =I8-A8 -> -46072
E9: 0 | F9: =C9+D9+E9 -> 0 | G9: =(C9*C$7+D9*D$7+E9*E$7) -> 0 | H9: =H8-F9 -> 125 | J9: =I9-A9 -> 0
E10: 0 | F10: =C10+D10+E10 -> 0 | G10: =(C10*C$7+D10*D$7+E10*E$7) -> 0 | H10: =H9-F10 -> 125 | J10: =I10-A10 -> 0
E11: 0 | F11: =C11+D11+E11 -> 0 | G11: =(C11*C$7+D11*D$7+E11*E$7) -> 0 | H11: =H10-F11 -> 125 | J11: =I11-A11 -> 0
E12: 0 | F12: =C12+D12+E12 -> 0 | G12: =(C12*C$7+D12*D$7+E12*E$7) -> 0 | H12: =H11-F12 -> 125 | J12: =I12-A12 -> 0
E13: 0 | F13: =C13+D13+E13 -> 0 | G13: =(C13*C$7+D13*D$7+E13*E$7) -> 0 | H13: =H12-F13 -> 125 | J13: =I13-A13 -> 0
E14: 0 | F14: =C14+D14+E14 -> 0 | G14: =(C14*C$7+D14*D$7+E14*E$7) -> 0 | H14: =H13-F14 -> 125 | J14: =I14-A14 -> 0
D15: 0 | E15: 0 | F15: =C15+D15+E15 -> 0 | G15: =(C15*C$7+D15*D$7+E15*E$7) -> 0 | H15: =H14-F15 -> 125 | J15: =I15-A15 -> 0
A16: Jumlah | C16: =SUM(C8:C15) -> 0 | D16: =SUM(D8:D15) -> 25 | E16: =SUM(E8:E15) -> 0 | F16: =SUM(F8:F15) -> 25 | G16: =SUM(G8:G15) -> 55500000 | H16: =H4-F16 -> 125
G17: Capai % | H17: =F8/H4 % -> 16.666667
A19: PRODUK | B19: D E K A B O N D | H19: TARGET | I19: PELUNASAN | K19: 46077
A20: TOKO | B20: PT. SUMBER MAKMUR - JOMBANG | H20: 150
A21: TANGGAL | B21: NO. SPB | C21: KEMASAN | F21: J U M L A H | H21: KURANG | I21: TANGGAL | J21: TEMPO
C22: 100 cc | D22: 500 cc | E22: 1000 cc | F22: DUS | G22: RUPIAH | H22: KG | J22: HARI
A23: berlaku | C23: 1276500 | D23: 2220000
A24: 46048 | B24: 24328 | C24: 15 | E24: 0 | F24: =C24+D24+E24 -> 15 | G24: =(C24*C$23+D24*D$23+E24*E$23) -> 19147500 | H24: =H20-F24 -> 135 | I24: ='[1]Area I '!$D$13 -> 46083 | J24: =I24-A24 -> 35
A25: 46071 | B25: 24334 | C25: 0 | D25: 50 | E25: 0 | F25: =C25+D25+E25 -> 50 | G25: =(C25*C$23+D25*D$23+E25*E$23) -> 111000000 | H25: =H24-F25 -> 85 | I25: ='[1]Area I '!$D$15 -> 0 | J25: =I25-A25 -> -46071
C26: 0 | E26: 0 | F26: =C26+D26+E26 -> 0 | G26: =(C26*C$23+D26*D$23+E26*E$23) -> 0 | H26: =H25-F26 -> 85 | J26: =I26-A26 -> 0
C27: 0 | E27: 0 | F27: =C27+D27+E27 -> 0 | G27: =(C27*C$23+D27*D$23+E27*E$23) -> 0 | H27: =H26-F27 -> 85 | J27: =I27-A27 -> 0
F28: =C28+D28+E28 -> 0 | G28: =(C28*C$23+D28*D$23+E28*E$23) -> 0 | H28: =H27-F28 -> 85 | J28: =I28-A28 -> 0
F29: 0 | G29: =(C29*C$23+D29*D$23+E29*E$23) -> 0 | H29: =H28-F29 -> 85 | J29: =I29-A29 -> 0
F30: =C30+D30+E30 -> 0 | G30: =(C30*C$23+D30*D$23+E30*E$23) -> 0 | H30: =H29-F30 -> 85 | J30: =I30-A30 -> 0
A31: Jumlah | C31: =SUM(C24:C30) -> 15 | D31: =SUM(D24:D30) -> 50 | E31: =SUM(E24:E30) -> 0 | F31: =SUM(F24:F30) -> 65 | G31: =SUM(G24:G30) -> 130147500 | H31: =H30-F31 -> 20
G32: Capai % | H32: =F31/H20% -> 43.333333
A34: PRODUK | B34: D E K A B O N D | H34: TARGET | I34: PELUNASAN | K34: 46062
A35: TOKO | B35: PT. ANUGERAH AGRO MANDIRI - BANYUWANGI | H35: 150
A36: TANGGAL | B36: NO. SPB | C36: KEMASAN | F36: J U M L A H | H36: KURANG | I36: TANGGAL | J36: TEMPO
C37: 100 cc | D37: 500 cc | E37: 1000 cc | F37: DUS | G37: RUPIAH | H37: KG | J37: HARI
A38: berlaku | C38: 1276500 | D38: 2220000
A39: 46063 | B39: 24284 | C39: 0 | D39: 50 | E39: 0 | F39: =C39+D39+E39 -> 50 | G39: =(C39*C$38+D39*D$38+E39*E$38) -> 111000000 | H39: =H35-F39 -> 100 | I39: ='[1]Area 4'!$D$42 -> 0 | J39: =I39-A39 -> -46063
A40: 46065 | B40: 24286 | C40: 10 | D40: 0 | E40: 0 | F40: =C40+D40+E40 -> 10 | G40: =(C40*C$38+D40*D$38+E40*E$38) -> 12765000 | H40: =H39-F40 -> 90 | I40: ='[1]Area 4'!$D$44 -> 0 | J40: =I40-A40 -> -46065
F41: =C41+D41+E41 -> 0 | G41: =(C41*C$38+D41*D$38+E41*E$38) -> 0 | H41: =H40-F41 -> 90 | J41: =I41-A41 -> 0
F42: =C42+D42+E42 -> 0 | G42: =(C42*C$38+D42*D$38+E42*E$38) -> 0 | H42: =H41-F42 -> 90 | J42: =I42-A42 -> 0
...

Sheet Vlmk
A1: PENJUALAN PRODAK YANG DIPROGAM BERDASARKAN PENCAPAIAN TOKO
A2: =GDSL!A2 -> TAHUN 2026
A3: PRODUK | B3: V E L I M E K 52 , 5 WP | I3: TARGET | J3: PELUNASAN | L3: 46077
A4: TOKO | B4: PT. SUMBER MAKMUR AGROINDO - JOMBANG | I4: 50
A5: TANGGAL | B5: NO. SPB | C5: KEMASAN | F5: J U M L A H | I5: KURANG | J5: TANGGAL | K5: TEMPO
C6: 50 gr | D6: 200 gr | E6: 500 gr | F6: KG | G6: RUPIAH | H6: DUS | I6: DUS | K6: HARI
A7: berlaku | B7: 45931 | C7: 4218000 | D7: 6549000 | E7: 9630360 | F7: 0.95
F8: =C8*2.5+D8*4*E8*6 -> 0 | G8: =(C8*C$7+D8*D$7+E8*E$7)*F$7 -> 0 | H8: =C8+D8+E8 -> 0 | I8: =I4-H8 -> 50 | K8: =J8-A8 -> 0
F9: =C9*2.5+D9*4*E9*6 -> 0 | G9: =(C9*C$7+D9*D$7+E9*E$7)*F$7 -> 0 | H9: =C9+D9+E9 -> 0 | I9: =I8-H9 -> 50 | K9: =J9-A9 -> 0
F10: =C10*2.5+D10*4*E10*6 -> 0 | G10: =(C10*C$7+D10*D$7+E10*E$7)*F$7 -> 0 | H10: =C10+D10+E10 -> 0 | I10: =I9-H10 -> 50 | K10: =J10-A10 -> 0
F11: =C11*2.5+D11*4*E11*6 -> 0 | G11: =(C11*C$7+D11*D$7+E11*E$7)*F$7 -> 0 | H11: =C11+D11+E11 -> 0 | I11: =I10-H11 -> 50 | K11: =J11-A11 -> 0
F12: =C12*2.5+D12*4*E12*6 -> 0 | G12: =(C12*C$7+D12*D$7+E12*E$7)*F$7 -> 0 | H12: =C12+D12+E12 -> 0 | I12: =I11-H12 -> 50 | K12: =J12-A12 -> 0
F13: =C13*2.5+D13*4*E13*6 -> 0 | G13: =(C13*C$7+D13*D$7+E13*E$7)*F$7 -> 0 | H13: =C13+D13+E13 -> 0 | I13: =I12-H13 -> 50 | K13: =J13-A13 -> 0
F14: =C14*2.5+D14*4*E14*6 -> 0 | G14: =(C14*C$7+D14*D$7+E14*E$7)*F$7 -> 0 | H14: =C14+D14+E14 -> 0 | I14: =I13-H14 -> 50 | K14: =J14-A14 -> 0
F15: =C15*2.5+D15*4*E15*6 -> 0 | G15: =(C15*C$7+D15*D$7+E15*E$7)*F$7 -> 0 | H15: =C15+D15+E15 -> 0 | I15: =I14-H15 -> 50 | K15: =J15-A15 -> 0
F16: =C16*2.5+D16*4*E16*6 -> 0 | G16: =(C16*C$7+D16*D$7+E16*E$7)*F$7 -> 0 | H16: =C16+D16+E16 -> 0 | I16: =I15-H16 -> 50 | K16: =J16-A16 -> 0
F17: =C17*2.5+D17*4*E17*6 -> 0 | G17: =(C17*C$7+D17*D$7+E17*E$7)*F$7 -> 0 | H17: =C17+D17+E17 -> 0 | I17: =I16-H17 -> 50 | K17: =J17-A17 -> 0
F18: =C18*2.5+D18*4*E18*6 -> 0 | G18: =(C18*C$7+D18*D$7+E18*E$7)*F$7 -> 0 | H18: =C18+D18+E18 -> 0 | I18: =I17-H18 -> 50 | K18: =J18-A18 -> 0
F19: =C19*2.5+D19*4*E19*6 -> 0 | G19: =(C19*C$7+D19*D$7+E19*E$7)*F$7 -> 0 | H19: =C19+D19+E19 -> 0 | I19: =I18-H19 -> 50 | K19: =J19-A19 -> 0
F20: =C20*2.5+D20*4*E20*6 -> 0 | G20: =(C20*C$7+D20*D$7+E20*E$7)*F$7 -> 0 | H20: =C20+D20+E20 -> 0 | I20: =I19-H20 -> 50 | K20: =J20-A20 -> 0
A21: Jumlah | C21: =SUM(C8:C20) -> 0 | D21: =SUM(D8:D20) -> 0 | E21: =SUM(E8:E20) -> 0 | F21: =SUM(F8:F20) -> 0 | G21: =SUM(G8:G20) -> 0 | H21: =SUM(H8:H20) -> 0 | I21: =I4-H21 -> 50
G22: Capai % | H22: =H21/I4% -> 0 | I22: =I21/I4% -> 100
A24: PRODUK | B24: V E L I M E K 52 , 5 WP | I24: TARGET | J24: PELUNASAN | L24: 46062
A25: TOKO | B25: PT. A N U G E R A H A G R O M A N D I R I - B A N Y U W A N G I | I25: 100
A26: TANGGAL | B26: NO. SPB | C26: KEMASAN | F26: J U M L A H | I26: KURANG | J26: TANGGAL | K26: TEMPO
C27: 50 gr | D27: 200 gr | E27: 500 gr | F27: KG | G27: RUPIAH | H27: DUS | I27: DUS | K27: HARI
A28: berlaku | B28: 45931 | C28: 4218000 | D28: 6549000 | E28: 9630360 | F28: 0.95
F29: =C29*2.5+D29*4+E29*6 -> 0 | G29: =(C29*C$28+D29*D$28+E29*E$28)*F$28 -> 0 | H29: =C29+D29+E29 -> 0 | I29: =I25-H29 -> 100 | J29: ='[1]Area 4'!$D$49 -> 0 | K29: =J29-A29 -> 0
F30: =C30*2.5+D30*4+E30*6 -> 0 | G30: =(C30*C$28+D30*D$28+E30*E$28)*F$28 -> 0 | H30: =C30+D30+E30 -> 0 | I30: =I29-H30 -> 100 | K30: =J30-A30 -> 0
F31: =C31*2.5+D31*4+E31*6 -> 0 | G31: =(C31*C$28+D31*D$28+E31*E$28)*F$28 -> 0 | H31: =C31+D31+E31 -> 0 | I31: =I30-H31 -> 100 | K31: =J31-A31 -> 0
F32: =C32*2.5+D32*4+E32*6 -> 0 | G32: =(C32*C$28+D32*D$28+E32*E$28)*F$28 -> 0 | H32: =C32+D32+E32 -> 0 | I32: =I31-H32 -> 100 | K32: =J32-A32 -> 0
F33: =C33*2.5+D33*4+E33*6 -> 0 | G33: =(C33*C$28+D33*D$28+E33*E$28)*F$28 -> 0 | H33: =C33+D33+E33 -> 0 | I33: =I32-H33 -> 100 | K33: =J33-A33 -> 0
F34: =C34*2.5+D34*4+E34*6 -> 0 | G34: =(C34*C$28+D34*D$28+E34*E$28)*F$28 -> 0 | H34: =C34+D34+E34 -> 0 | I34: =I33-H34 -> 100 | K34: =J34-A34 -> 0
F35: =C35*2.5+D35*4+E35*6 -> 0 | G35: =(C35*C$28+D35*D$28+E35*E$28)*F$28 -> 0 | H35: =C35+D35+E35 -> 0 | I35: =I34-H35 -> 100 | K35: =J35-A35 -> 0
F36: =C36*2.5+D36*4+E36*6 -> 0 | G36: =(C36*C$28+D36*D$28+E36*E$28)*F$28 -> 0 | H36: =C36+D36+E36 -> 0 | I36: =I35-H36 -> 100 | K36: =J36-A36 -> 0
F37: =C37*2.5+D37*4+E37*6 -> 0 | G37: =(C37*C$28+D37*D$28+E37*E$28)*F$28 -> 0 | H37: =C37+D37+E37 -> 0 | I37: =I36-H37 -> 100 | K37: =J37-A37 -> 0
F38: =C38*2.5+D38*4+E38*6 -> 0 | G38: =(C38*C$28+D38*D$28+E38*E$28)*F$28 -> 0 | H38: =C38+D38+E38 -> 0 | I38: =I37-H38 -> 100 | K38: =J38-A38 -> 0
F39: =C39*2.5+D39*4+E39*6 -> 0 | G39: =(C39*C$28+D39*D$28+E39*E$28)*F$28 -> 0 | H39: =C39+D39+E39 -> 0 | I39: =I38-H39 -> 100 | K39: =J39-A39 -> 0
F40: =C40*2.5+D40*4+E40*6 -> 0 | G40: =(C40*C$28+D40*D$28+E40*E$28)*F$28 -> 0 | H40: =C40+D40+E40 -> 0 | I40: =I39-H40 -> 100 | K40: =J40-A40 -> 0
F41: =C41*2.5+D41*4+E41*6 -> 0 | G41: =(C41*C$28+D41*D$28+E41*E$28)*F$28 -> 0 | H41: =C41+D41+E41 -> 0 | I41: =I40-H41 -> 100 | K41: =J41-A41 -> 0
...

Sheet Msg
A1: PENJUALAN PRODAK YANG DIPROGAM BERDASARKAN PENCAPAIAN TOKO
A2: =GDSL!A2 -> TAHUN 2026
A3: PRODUK | B3: M A S A L G I N 5 0 W P | K3: TARGET | L3: PELUNASAN | N3: 46077
A4: TOKO | B4: P T . S U M B E R M A K M U R A G R O I N D O - J O M B A N G | K4: 50
A5: TANGGAL | B5: No. SPB | C5: KEMASAN | H5: J U M L A H | K5: KURANG | L5: TANGGAL | M5: TEMPO
C6: 50 gr | D6: 100 gr | E6: 200 gr | F6: 500 gr | G6: 25 Kg | H6: KG | I6: RUPIAH | J6: DUS | K6: DUS | M6: HARI
A7: berlaku | B7: 45931 | D7: 1145520 | E7: 2264400 | F7: 2384280 | H7: 0.98
G8: 0 | H8: =(C8*2.4+D8*2.4+E8*2.4+F8*6+G8*25) -> 0 | I8: =(C8*C$7+D8*D$7+E8*E$7+F8*F$7)*H$7 -> 0 | J8: =(C8+D8+E8+F8+G8) -> 0 | K8: =K4-J8 -> 50 | M8: =L8-A8 -> 0
G9: 0 | H9: =(C9*2.4+D9*2.4+E9*2.4+F9*6+G9*25) -> 0 | I9: =(C9*C$7+D9*D$7+E9*E$7+F9*F$7)*H$7 -> 0 | J9: =(C9+D9+E9+F9+G9) -> 0 | K9: =K8-J9 -> 50 | M9: =L9-A9 -> 0
G10: 0 | H10: =(C10*2.4+D10*2.4+E10*2.4+F10*6+G10*25) -> 0 | I10: =(C10*C$7+D10*D$7+E10*E$7+F10*F$7)*H$7 -> 0 | J10: =(C10+D10+E10+F10+G10) -> 0 | K10: =K9-J10 -> 50 | M10: =L10-A10 -> 0
H11: =(C11*2.4+D11*2.4+E11*2.4+F11*6+G11*25) -> 0 | I11: =(C11*C$7+D11*D$7+E11*E$7+F11*F$7)*H$7 -> 0 | J11: =(C11+D11+E11+F11+G11) -> 0 | K11: =K10-J11 -> 50 | M11: =L11-A11 -> 0
H12: =(C12*2.4+D12*2.4+E12*2.4+F12*6+G12*25) -> 0 | I12: =(C12*C$7+D12*D$7+E12*E$7+F12*F$7)*H$7 -> 0 | J12: =(C12+D12+E12+F12+G12) -> 0 | K12: =K11-J12 -> 50 | M12: =L12-A12 -> 0
H13: =(C13*2.4+D13*2.4+E13*2.4+F13*6+G13*25) -> 0 | I13: =(C13*C$7+D13*D$7+E13*E$7+F13*F$7)*H$7 -> 0 | J13: =(C13+D13+E13+F13+G13) -> 0 | K13: =K12-J13 -> 50 | M13: =L13-A13 -> 0
H14: =(C14*2.4+D14*2.4+E14*2.4+F14*6+G14*25) -> 0 | I14: =(C14*C$7+D14*D$7+E14*E$7+F14*F$7)*H$7 -> 0 | J14: =(C14+D14+E14+F14+G14) -> 0 | K14: =K13-J14 -> 50 | M14: =L14-A14 -> 0
A15: Jumlah | C15: =SUM(C8:C14) -> 0 | D15: =SUM(D8:D14) -> 0 | E15: =SUM(E8:E14) -> 0 | F15: =SUM(F8:F14) -> 0 | G15: =SUM(G8:G14) -> 0 | H15: =SUM(H8:H14) -> 0 | I15: =SUM(I8:I14) -> 0 | J15: =(C15+D15+E15+F15+G15) -> 0 | K15: =K4-J15 -> 50
I16: Capai % | J16: =J15/K4% -> 0 | K16: =K15/K4% -> 100
A19: PRODUK | B19: M A S A L G I N 5 0 W P | K19: TARGET | L19: PELUNASAN | N19: 46062
A20: TOKO | B20: P T. A N U G E R A H A G R O M - B A N Y U W A N G I | K20: 700
A21: TANGGAL | B21: No. SPB | C21: KEMASAN | H21: J U M L A H | K21: KURANG | L21: TANGGAL | M21: TEMPO
C22: 50 gr | D22: 100 gr | E22: 200 gr | F22: 500 gr | G22: 25 Kg | H22: KG | I22: RUPIAH | J22: DUS | K22: DUS | M22: HARI
A23: berlaku | B23: 45931 | C23: 0 | D23: 1110000 | E23: 2264400 | F23: 2384280 | H23: 0.98
A24: 46063 | B24: 24285 | E24: 0 | F24: 50 | H24: =(E24*2.4+F24*6+G24*25) -> 300 | I24: =(E24*E$23+F24*F$23 ) *H$23 -> 116829720 | J24: =(C24+D24+E24+F24+G24) -> 50 | K24: =K20-J24 -> 650 | L24: ='[1]Area 4'!$D$43 -> 0 | M24: =L24-A24 -> -46063
A25: 46076 | B25: 24291 | E25: 50 | F25: 100 | H25: =(E25*2.4+F25*6+G25*25) -> 720 | I25: =(E25*E$23+F25*F$23 ) *H$23 -> 344615040 | J25: =(C25+D25+E25+F25+G25) -> 150 | K25: =K24-J25 -> 500 | L25: ='[1]Area 4'!$D$47 -> 0 | M25: =L25-A25 -> -46076
H26: =(E26*2.4+F26*6+G26*25) -> 0 | I26: =(E26*E$23+F26*F$23 ) *H$23 -> 0 | J26: =(C26+D26+E26+F26+G26) -> 0 | K26: =K25-J26 -> 500 | M26: =L26-A26 -> 0
H27: =(E27*2.4+F27*6+G27*25) -> 0 | I27: =(E27*E$23+F27*F$23 ) *H$23 -> 0 | J27: =(C27+D27+E27+F27+G27) -> 0 | K27: =K26-J27 -> 500 | M27: =L27-A27 -> 0
H28: =(E28*2.4+F28*6+G28*25) -> 0 | I28: =(E28*E$23+F28*F$23 ) *H$23 -> 0 | J28: =(C28+D28+E28+F28+G28) -> 0 | K28: =K27-J28 -> 500 | M28: =L28-A28 -> 0
H29: =(E29*2.4+F29*6+G29*25) -> 0 | I29: =(E29*E$23+F29*F$23 ) *H$23 -> 0 | J29: =(C29+D29+E29+F29+G29) -> 0 | K29: =K28-J29 -> 500 | M29: =L29-A29 -> 0
H30: =(E30*2.4+F30*6+G30*25) -> 0 | I30: =(E30*E$23+F30*F$23 ) *H$23 -> 0 | J30: =(C30+D30+E30+F30+G30) -> 0 | K30: =K29-J30 -> 500 | M30: =L30-A30 -> 0
H31: =(E31*2.4+F31*6+G31*25) -> 0 | I31: =(E31*E$23+F31*F$23 ) *H$23 -> 0 | J31: =(C31+D31+E31+F31+G31) -> 0 | K31: =K30-J31 -> 500 | M31: =L31-A31 -> 0
H32: =(E32*2.4+F32*6+G32*25) -> 0 | I32: =(E32*E$23+F32*F$23 ) *H$23 -> 0 | J32: =(C32+D32+E32+F32+G32) -> 0 | K32: =K31-J32 -> 500 | M32: =L32-A32 -> 0
H33: =(E33*2.4+F33*6+G33*25) -> 0 | I33: =(E33*E$23+F33*F$23 ) *H$23 -> 0 | J33: =(C33+D33+E33+F33+G33) -> 0 | K33: =K32-J33 -> 500 | M33: =L33-A33 -> 0
H34: =(E34*2.4+F34*6+G34*25) -> 0 | I34: =(E34*E$23+F34*F$23 ) *H$23 -> 0 | J34: =(C34+D34+E34+F34+G34) -> 0 | K34: =K33-J34 -> 500 | M34: =L34-A34 -> 0
H35: =(E35*2.4+F35*6+G35*25) -> 0 | I35: =(E35*E$23+F35*F$23 ) *H$23 -> 0 | J35: =(C35+D35+E35+F35+G35) -> 0 | K35: =K34-J35 -> 500 | M35: =L35-A35 -> 0
H36: =(E36*2.4+F36*6+G36*25) -> 0 | I36: =(E36*E$23+F36*F$23 ) *H$23 -> 0 | J36: =(C36+D36+E36+F36+G36) -> 0 | K36: =K35-J36 -> 500 | M36: =L36-A36 -> 0
A37: Jumlah | C37: =SUM(C24:C34) -> 0 | D37: =SUM(D24:D34) -> 0 | E37: =SUM(E24:E36) -> 50 | F37: =SUM(F24:F36) -> 150 | H37: =SUM(H24:H36) -> 1020 | I37: =SUM(I24:I36) -> 461444760 | J37: =SUM(J24:J36) -> 200 | K37: =K36-J37 -> 300
I38: Capai % | J38: =J37/K20% -> 28.571429 | K38: =K37/K20% -> 42.857143
A41: Total Jumlah DUS MASALGIN Toko yang ditarget | G41: =K20+K4 -> 750
A44: Total Jumlah DUS pencapaian Toko | G44: =J37+J15 -> 200
A46: Total jumlah kekurangan DUS Toko | G46: =G41-G44 -> 550
A48: Rata-2 % pencapaian target Toko | G48: =G44/G41% -> 26.666667
...

Sheet Dkprm
A1: PENJUALAN PRODAK YANG DIPROGAM BERDASARKAN PENCAPAIAN TOKO
A2: =GDSL!A2 -> TAHUN 2026
A3: PRODUK | B3: DEKAPIRIM 400 SC | I3: TARGET | J3: PELUNASAN | L3: 46062
A4: TOKO | B4: PT. KARISMA INDOAGRO UNIVERSAL - JEMBER | I4: 1000
A5: TANGGAL | B5: NO. SPB | C5: KEMASAN | F5: J U M L A H | I5: KURANG | J5: TANGGAL | K5: TEMPO
C6: 100 CC | D6: 500 CC | E6: 1000 CC | F6: DUS | G6: RUPIAH | H6: LITER | I6: LITER | K6: HARI
A7: berlaku | B7: 45931 | C7: 4884000 | D7: 9146400 | E7: 10642680 | F7: 0.95
A8: 46034 | B8: 24278 | C8: 20 | D8: 5 | E8: 0 | G8: =(C$7*C8+D$7*D8+E$7*E$8)*F$7 -> 136241400 | H8: =C8*5+D8*10+E8*12 -> 150 | I8: =I4-H8 -> 850 | J8: ='[1]Area 3'!$D$12 -> 46063 | K8: =J8-A8 -> 29
G9: =(C$7*C9+D$7*D9+E$7*E$8)*F$7 -> 0 | H9: =C9*5+D9*10+E9*12 -> 0 | I9: =I8-H9 -> 850 | K9: =J9-A9 -> 0
G10: =(C$7*C10+D$7*D10+E$7*E$8)*F$7 -> 0 | H10: =C10*5+D10*10+E10*12 -> 0 | I10: =I9-H10 -> 850 | K10: =J10-A10 -> 0
G11: =(C$7*C11+D$7*D11+E$7*E$8)*F$7 -> 0 | H11: =C11*5+D11*10+E11*12 -> 0 | I11: =I10-H11 -> 850 | K11: =J11-A11 -> 0
G12: =(C$7*C12+D$7*D12+E$7*E$8)*F$7 -> 0 | H12: =C12*5+D12*10+E12*12 -> 0 | I12: =I11-H12 -> 850 | K12: =J12-A12 -> 0
G13: =(C$7*C13+D$7*D13+E$7*E$8)*F$7 -> 0 | H13: =C13*5+D13*10+E13*12 -> 0 | I13: =I12-H13 -> 850 | K13: =J13-A13 -> 0
G14: =(C$7*C14+D$7*D14+E$7*E$8)*F$7 -> 0 | H14: =C14*5+D14*10+E14*12 -> 0 | I14: =I13-H14 -> 850 | K14: =J14-A14 -> 0
G15: =(C$7*C15+D$7*D15+E$7*E$8)*F$7 -> 0 | H15: =C15*5+D15*10+E15*12 -> 0 | I15: =I14-H15 -> 850 | K15: =J15-A15 -> 0
A16: Jumlah | C16: =SUM(C8:C15) -> 20 | D16: =SUM(D8:D15) -> 5 | E16: =SUM(E8:E15) -> 0 | F16: =SUM(F8:F15) -> 0 | G16: =SUM(G8:G15) -> 136241400 | H16: =SUM(H8:H15) -> 150 | I16: =I4-H16 -> 850
G17: Capai % | H17: =H16/I4% -> 15 | I17: =I16/I4% -> 85
A21: Total Jumlah LITER DEKAPIRIM 400 SC Toko yang ditarget | G21: =I4 -> 1000
A23: Total Jumlah LITER pencapaian Toko target | G23: =H16 -> 150
A25: Total jumlah kekurangan DUS capai target | G25: =G21-G23 -> 850
A27: Rata-2 % pencapaian target Toko | G27: =G23/G21% -> 15
A29: Rata-2 % kurang pencapaian target Toko | G29: =G25/G21% -> 85
A31: Total jumlah DUS pencapaian target Toko | G31: =F16 -> 0
A33: Total nilai Jumlah RUPIAH Toko ditarget | F33: =G16 -> 136241400

Sheet Dktn
A1: PENJUALAN PRODAK YANG DIPROGAM BERDASARKAN PENCAPAIAN TOKO
A2: =GDSL!A2 -> TAHUN 2026
A3: PRODUK | B3: D E K T I N 3 0 WG | I3: TARGET | J3: PELUNASAN | L3: 46062
A4: TOKO | B4: PT. KARISMA INDOAGRO UNIVERSAL - JEMBER | I4: 1000
A5: TANGGAL | B5: NO. SPB | C5: KEMASAN | F5: J U M L A H | I5: KURANG | J5: TANGGAL | K5: TEMPO
C6: 50 gr | D6: 200 gr | E6: 500 gr | F6: DUS | G6: RUPIAH | H6: KG | I6: KG | K6: HARI
A7: berlaku | B7: 45931 | C7: 3885000 | D7: 5727600 | E7: 8178480 | F7: 0.95
A8: 46077 | B8: 24292 | C8: 5 | D8: 0 | E8: 0 | F8: =C8+D8+E8 -> 5 | G8: =(C8*C$7+D8*D$7+E8*E$7)*F$7 -> 18453750 | H8: =C8*2.5+D8*4+E8*6 -> 12.5 | I8: =I4-H8 -> 987.5 | J8: ='[1]Area 3'!$D$17 -> 0 | K8: =J8-A8 -> -46077
F9: =C9+D9+E9 -> 0 | G9: =(C9*C$7+D9*D$7+E9*E$7)*F$7 -> 0 | H9: =C9*2.5+D9*4+E9*6 -> 0 | I9: =I8-H9 -> 987.5 | K9: =J9-A9 -> 0
F10: =C10+D10+E10 -> 0 | G10: =(C10*C$7+D10*D$7+E10*E$7)*F$7 -> 0 | H10: =C10*2.5+D10*4+E10*6 -> 0 | I10: =I9-H10 -> 987.5 | K10: =J10-A10 -> 0
F11: =C11+D11+E11 -> 0 | G11: =(C11*C$7+D11*D$7+E11*E$7)*F$7 -> 0 | H11: =C11*2.5+D11*4+E11*6 -> 0 | I11: =I10-H11 -> 987.5 | K11: =J11-A11 -> 0
F12: =C12+D12+E12 -> 0 | G12: =(C12*C$7+D12*D$7+E12*E$7)*F$7 -> 0 | H12: =C12*2.5+D12*4+E12*6 -> 0 | I12: =I11-H12 -> 987.5 | K12: =J12-A12 -> 0
F13: 0 | G13: =(C13*C$7+D13*D$7+E13*E$7)*F$7 -> 0 | H13: =C13*2.5+D13*4+E13*6 -> 0 | I13: =I12-H13 -> 987.5 | K13: =J13-A13 -> 0
F14: =C14+D14+E14 -> 0 | G14: =(C14*C$7+D14*D$7+E14*E$7)*F$7 -> 0 | H14: =C14*2.5+D14*4+E14*6 -> 0 | I14: =I13-H14 -> 987.5 | K14: =J14-A14 -> 0
F15: =C15+D15+E15 -> 0 | G15: =(C15*C$7+D15*D$7+E15*E$7)*F$7 -> 0 | H15: =C15*2.5+D15*4+E15*6 -> 0 | I15: =I14-H15 -> 987.5 | K15: =J15-A15 -> 0
F16: =C16+D16+E16 -> 0 | G16: =(C16*C$7+D16*D$7+E16*E$7)*F$7 -> 0 | H16: =C16*2.5+D16*4+E16*6 -> 0 | I16: =I15-H16 -> 987.5 | K16: =J16-A16 -> 0
F17: =C17+D17+E17 -> 0 | G17: =(C17*C$7+D17*D$7+E17*E$7)*F$7 -> 0 | H17: =C17*2.5+D17*4+E17*6 -> 0 | I17: =I16-H17 -> 987.5 | K17: =J17-A17 -> 0
F18: =C18+D18+E18 -> 0 | G18: =(C18*C$7+D18*D$7+E18*E$7)*F$7 -> 0 | H18: =C18*2.5+D18*4+E18*6 -> 0 | I18: =I17-H18 -> 987.5 | K18: =J18-A18 -> 0
F19: =C19+D19+E19 -> 0 | G19: =(C19*C$7+D19*D$7+E19*E$7)*F$7 -> 0 | H19: =C19*2.5+D19*4+E19*6 -> 0 | I19: =I18-H19 -> 987.5 | K19: =J19-A19 -> 0
F20: =C20+D20+E20 -> 0 | G20: =(C20*C$7+D20*D$7+E20*E$7)*F$7 -> 0 | H20: =C20*2.5+D20*4+E20*6 -> 0 | I20: =I19-H20 -> 987.5 | K20: =J20-A20 -> 0
A21: Jumlah | C21: =SUM(C8:C20) -> 5 | D21: =SUM(D8:D20) -> 0 | E21: =SUM(E8:E20) -> 0 | F21: =SUM(F8:F20) -> 5 | G21: =SUM(G8:G20) -> 18453750 | H21: =SUM(H8:H20) -> 12.5 | I21: =I4-H21 -> 987.5
G22: Capai % | H22: =H21/I4% -> 1.25 | I22: =I21/I4% -> 98.75
A26: Total Jumlah DUS DEKTIN Toko | F26: =I4 -> 1000
A28: Total Jumlah DUS pencapaian Toko target | F28: =F21 -> 5
A30: Total jumlah kekurangan DUS capai target | F30: =F26-F28 -> 995
A32: Rata-2 % pencapaian target Toko | F32: =F28/F26% -> 0.5
A34: Rata-2 % kurang pencapaian target Toko | F34: =F30/F26% -> 99.5
A36: Total jumlah LITER pencapaian target Toko | F36: =H21 -> 12.5
A38: Total nilai Jumlah RUPIAH Toko ditarget | F38: =G21 -> 18453750

Sheet Dmc
A1: PENJUALAN PRODAK YANG DIPROGAM BERDASARKAN PENCAPAIAN TOKO
A2: =GDSL!A2 -> TAHUN 2026
A3: PRODUK | B3: D I M A C I D E 400 EC | I3: TARGET | J3: PELUNASAN | L3: 46062
A4: TOKO | B4: PT. TUNAS ABADI INDOAGRO - BANYUWANGI | I4: 100
A5: TANGGAL | B5: NO. SPB | C5: KEMASAN | F5: J U M L A H | I5: KURANG | J5: TANGGAL | K5: TEMPO
C6: 100 cc | D6: 500 cc | E6: 1000 cc | F6: DUS | G6: RUPIAH | H6: LT | I6: KG | K6: HARI
A7: berlaku | D7: 2200000
F8: =C8+D8+E8 -> 0 | G8: =(C8*C$7+D8*D$7+E8*E$7) -> 0 | H8: =C8*5+D8*10+E8*6 -> 0 | I8: =I4-H8 -> 100 | K8: =J8-A8 -> 0
F9: =C9+D9+E9 -> 0 | G9: =(C9*C$7+D9*D$7+E9*E$7) -> 0 | H9: =C9*5+D9*10+E9*6 -> 0 | I9: =I8-H9 -> 100 | K9: =J9-A9 -> 0
F10: =C10+D10+E10 -> 0 | G10: =(C10*C$7+D10*D$7+E10*E$7) -> 0 | H10: =C10*5+D10*10+E10*6 -> 0 | I10: =I9-H10 -> 100 | K10: =J10-A10 -> 0
F11: =C11+D11+E11 -> 0 | G11: =(C11*C$7+D11*D$7+E11*E$7) -> 0 | H11: =C11*5+D11*10+E11*6 -> 0 | I11: =I10-H11 -> 100 | K11: =J11-A11 -> 0
F12: =C12+D12+E12 -> 0 | G12: =(C12*C$7+D12*D$7+E12*E$7) -> 0 | H12: =C12*5+D12*10+E12*6 -> 0 | I12: =I11-H12 -> 100 | K12: =J12-A12 -> 0
A13: Jumlah | C13: =SUM(C8:C12) -> 0 | D13: =SUM(D8:D12) -> 0 | E13: =SUM(E8:E12) -> 0 | F13: =SUM(F8:F12) -> 0 | G13: =SUM(G8:G12) -> 0 | H13: =SUM(H8:H12) -> 0 | I13: =I4-H13 -> 100
G14: Capai % | H14: =H13/I4% -> 0 | I14: =I13/I4% -> 100
A16: PRODUK | B16: D I M A C I D E 400 EC | I16: TARGET | J16: PELUNASAN | L16: 46083
A17: TOKO | B17: PT. SUMBER MAKMUR AGRIKULTUR - MALANG | I17: 100
A18: TANGGAL | B18: NO. SPB | C18: KEMASAN | F18: J U M L A H | I18: KURANG | J18: TANGGAL | K18: TEMPO
C19: 100 cc | D19: 500 cc | E19: 1000 cc | F19: DUS | G19: RUPIAH | H19: KG | I19: KG | K19: HARI
A20: berlaku | D20: 2200000
F21: =C21+D21+E21 -> 0 | G21: =(C21*C$20+D21*D$20+E21*E$20) -> 0 | H21: =C21*5+D21*10+E21*6 -> 0 | I21: =I17-H21 -> 100 | K21: =J21-A21 -> 0
F22: =C22+D22+E22 -> 0 | G22: =(C22*C$20+D22*D$20+E22*E$20) -> 0 | H22: =C22*5+D22*10+E22*6 -> 0 | I22: =I21-H22 -> 100 | K22: =J22-A22 -> 0
F23: =C23+D23+E23 -> 0 | G23: =(C23*C$20+D23*D$20+E23*E$20) -> 0 | H23: =C23*5+D23*10+E23*6 -> 0 | I23: =I22-H23 -> 100 | K23: =J23-A23 -> 0
F24: =C24+D24+E24 -> 0 | G24: =(C24*C$20+D24*D$20+E24*E$20) -> 0 | H24: =C24*5+D24*10+E24*6 -> 0 | I24: =I23-H24 -> 100 | K24: =J24-A24 -> 0
